<robot name="onshape">
    <link name="world"/>

    <joint name="fixed" type="fixed">
        <parent link="world"/>
        <child link="body2"/>
    </joint>
    <link name="body2">
        <visual>
            <origin xyz="-2.0251919608103787686e-07 -9.3350295535953844076e-09 0.2000000000000000111" rpy="0 -0 0" />
            <geometry>
                <mesh filename="../meshes/body2.obj"/>
            </geometry>
            <material name="body2_material">
                <color rgba="0.49803921568627451677 0.49803921568627451677 0.49803921568627451677 1.0"/>
            </material>
        </visual>
        <collision>
            <origin xyz="-2.0251919608103787686e-07 -9.3350295535953844076e-09 0.2000000000000000111" rpy="0 -0 0" />
            <geometry>
                <mesh filename="../meshes/body2.obj"/>
            </geometry>
        </collision>
        <inertial>
            <origin xyz="4.8159086971461754611e-05 -0.0014156634461524751547 0.22478087637914107022" rpy="0 0 0"/>
            <mass value="1.3612542756189531801" />
            <inertia ixx="0.0077625706777320196972" ixy="2.5091052185424148231e-06" ixz="-5.8608327827100554163e-07" iyy="0.0063611320539585245251" iyz="-1.739803642137599792e-05" izz="0.013115144217312024733" />
        </inertial>
    </link>

    <link name="coxa">
        <visual>
            <origin xyz="0.044924999999999715161 3.2028136856521692566e-16 0.024449999999999999512" rpy="1.570796326794896336 4.1572969705147322145e-27 -6.0505089188012136129e-58" />
            <geometry>
                <mesh filename="../meshes/coxa.obj"/>
            </geometry>
            <material name="coxa_material">
                <color rgba="0.2313725490196078538 0.38039215686274507888 0.7058823529411765163 1.0"/>
            </material>
        </visual>
        <collision>
            <origin xyz="0.044924999999999715161 3.2028136856521692566e-16 0.024449999999999999512" rpy="1.570796326794896336 4.1572969705147322145e-27 -6.0505089188012136129e-58" />
            <geometry>
                <mesh filename="../meshes/coxa.obj"/>
            </geometry>
        </collision>
        <inertial>
            <origin xyz="0.032100077240121795141 0.0015740371043174818718 0.033819596679097937986" rpy="0 0 0"/>
            <mass value="0.13178847096179543974" />
            <inertia ixx="0.00011206373196826075725" ixy="-2.7238887323284798804e-06" ixz="4.5419611014534278721e-06" iyy="0.00015582474539323191054" iyz="1.6739702901874812073e-06" izz="8.7721551578304402452e-05" />
        </inertial>
    </link>

    <link name="femur">
        <visual>
            <origin xyz="0.11831370849898502351 0 0.034149999999999965106" rpy="2.5412593609926780274e-16 2.8723936427800494222e-16 4.0353255554885214929e-17" />
            <geometry>
                <mesh filename="../meshes/femur.obj"/>
            </geometry>
            <material name="femur_material">
                <color rgba="0.97254901960784312376 0.52941176470588235947 0.0039215686274509803377 1.0"/>
            </material>
        </visual>
        <collision>
            <origin xyz="0.11831370849898502351 0 0.034149999999999965106" rpy="2.5412593609926780274e-16 2.8723936427800494222e-16 4.0353255554885214929e-17" />
            <geometry>
                <mesh filename="../meshes/femur.obj"/>
            </geometry>
        </collision>
        <inertial>
            <origin xyz="0.060855439588990166422 -1.5373120777950829722e-09 0.035514840700278334229" rpy="0 0 0"/>
            <mass value="0.12356537633038003343" />
            <inertia ixx="0.00012639156802844351245" ixy="-3.3471051787725817595e-06" ixz="4.1877477426023482265e-07" iyy="0.00033659596516426965821" iyz="-1.0699466471115516508e-13" izz="0.00024640255809226478808" />
        </inertial>
    </link>

    <link name="tibia">
        <visual>
            <origin xyz="0.21300366849942781178 -0.059547886795041582442 0.034350000000001150446" rpy="4.3217611766192633508e-16 2.3241406019702971832e-16 -0.2730770352191039807" />
            <geometry>
                <mesh filename="../meshes/tibia.obj"/>
            </geometry>
            <material name="tibia_material">
                <color rgba="0.49803921568627451677 0.49803921568627451677 0.49803921568627451677 1.0"/>
            </material>
        </visual>
        <collision>
            <origin xyz="0.21300366849942781178 -0.059547886795041582442 0.034350000000001150446" rpy="4.3217611766192633508e-16 2.3241406019702971832e-16 -0.2730770352191039807" />
            <geometry>
                <mesh filename="../meshes/tibia.obj"/>
            </geometry>
        </collision>
        <inertial>
            <origin xyz="0.082779557898568056906 -0.01049832662442924669 0.033115642475337041251" rpy="0 0 0"/>
            <mass value="0.17582156291145253912" />
            <inertia ixx="9.4427777285217644708e-05" ixy="0.0001650846023614744142" ixz="-1.7210628936254655325e-05" iyy="0.00087082283180923134892" iyz="2.1968964051795956221e-06" izz="0.00091072918862152333567" />
        </inertial>
    </link>

    <joint name="Femur-Tibia1" type="revolute">
        <origin xyz="0.11831370849898502351 0 -6.9388939039072283776e-18" rpy="-6.0759172493477425425e-14 3.0838881427276329573e-15 -2.4958208303518918392" />
        <parent link="femur" />
        <child link="tibia" />
        <axis xyz="0 0 1"/>
        <limit effort="1" velocity="20" lower="-2.4958208303518913951" upper="0.64577182323790194296"/>
        <joint_properties friction="0.0"/>
    </joint>

    <joint name="Coxa-Femur1" type="revolute">
        <origin xyz="0.044924999999999742917 0.034150000000001574929 0.024449999999999999512" rpy="-1.570796326794896336 -0.78539816339743095952 3.141592653589793116" />
        <parent link="coxa" />
        <child link="femur" />
        <axis xyz="0 0 1"/>
        <limit effort="1" velocity="20" lower="-0.785398163397448279" upper="2.356194490192344837"/>
        <joint_properties friction="0.0"/>
    </joint>

    <joint name="Body-Coxa1" type="revolute">
        <origin xyz="-0.12499582345459463173 -2.791807616543980008e-06 0.1862000000000000044" rpy="1.344277160988364166e-25 5.5511151231271693717e-17 -3.141592653589793116" />
        <parent link="body2" />
        <child link="coxa" />
        <axis xyz="0 0 1"/>
        <limit effort="1" velocity="20" lower="-1.0471975511965976313" upper="1.0471975511965976313"/>
        <joint_properties friction="0.0"/>
    </joint>

    <link name="coxa_2">
        <visual>
            <origin xyz="0.044924999999999687406 3.1996923692415371598e-16 0.024449999999999999512" rpy="1.570796326794896336 4.157296970514732932e-27 8.8092628559618404695e-18" />
            <geometry>
                <mesh filename="../meshes/coxa.obj"/>
            </geometry>
            <material name="coxa_material">
                <color rgba="0.2313725490196078538 0.38039215686274507888 0.7058823529411765163 1.0"/>
            </material>
        </visual>
        <collision>
            <origin xyz="0.044924999999999687406 3.1996923692415371598e-16 0.024449999999999999512" rpy="1.570796326794896336 4.157296970514732932e-27 8.8092628559618404695e-18" />
            <geometry>
                <mesh filename="../meshes/coxa.obj"/>
            </geometry>
        </collision>
        <inertial>
            <origin xyz="0.032100077240121767386 0.0015740371043174812213 0.033819596679097937986" rpy="0 0 0"/>
            <mass value="0.13178847096179543974" />
            <inertia ixx="0.00011206373196826073014" ixy="-2.7238887323284917389e-06" ixz="4.5419611014534270251e-06" iyy="0.00015582474539323191054" iyz="1.6739702901874812073e-06" izz="8.7721551578304402452e-05" />
        </inertial>
    </link>

    <link name="femur_2">
        <visual>
            <origin xyz="0.11831370849898513453 5.5511151231257827021e-17 0.034149999999999985922" rpy="1.978241163037608966e-16 2.3486853486126912247e-16 3.3140008060504894976e-17" />
            <geometry>
                <mesh filename="../meshes/femur.obj"/>
            </geometry>
            <material name="femur_material">
                <color rgba="0.97254901960784312376 0.52941176470588235947 0.0039215686274509803377 1.0"/>
            </material>
        </visual>
        <collision>
            <origin xyz="0.11831370849898513453 5.5511151231257827021e-17 0.034149999999999985922" rpy="1.978241163037608966e-16 2.3486853486126912247e-16 3.3140008060504894976e-17" />
            <geometry>
                <mesh filename="../meshes/femur.obj"/>
            </geometry>
        </collision>
        <inertial>
            <origin xyz="0.060855439588990277444 -1.5373120219743447143e-09 0.035514840700278355046" rpy="0 0 0"/>
            <mass value="0.12356537633038003343" />
            <inertia ixx="0.00012639156802844351245" ixy="-3.3471051787726431694e-06" ixz="4.1877477426021857021e-07" iyy="0.00033659596516426954979" iyz="-1.0699470277394574737e-13" izz="0.00024640255809226478808" />
        </inertial>
    </link>

    <link name="tibia_2">
        <visual>
            <origin xyz="0.21300366849942770076 -0.059547886795041610197 0.03435000000000112963" rpy="4.0425160417698567596e-16 3.0393907413155410649e-16 -0.27307703521910409172" />
            <geometry>
                <mesh filename="../meshes/tibia.obj"/>
            </geometry>
            <material name="tibia_material">
                <color rgba="0.49803921568627451677 0.49803921568627451677 0.49803921568627451677 1.0"/>
            </material>
        </visual>
        <collision>
            <origin xyz="0.21300366849942770076 -0.059547886795041610197 0.03435000000000112963" rpy="4.0425160417698567596e-16 3.0393907413155410649e-16 -0.27307703521910409172" />
            <geometry>
                <mesh filename="../meshes/tibia.obj"/>
            </geometry>
        </collision>
        <inertial>
            <origin xyz="0.082779557898567973639 -0.010498326624429260567 0.033115642475337034312" rpy="0 0 0"/>
            <mass value="0.17582156291145253912" />
            <inertia ixx="9.442777728521760405e-05" ixy="0.00016508460236147435999" ixz="-1.7210628936254584174e-05" iyy="0.00087082283180923156576" iyz="2.1968964051795761404e-06" izz="0.00091072918862152376935" />
        </inertial>
    </link>

    <joint name="Femur-Tibia2" type="revolute">
        <origin xyz="0.11831370849898652231 1.0547118733938987134e-15 -4.3715031594615538779e-16" rpy="-2.033122730806796144e-15 1.1419834053731681848e-16 -2.4958208303518882865" />
        <parent link="femur_2" />
        <child link="tibia_2" />
        <axis xyz="0 0 1"/>
        <limit effort="1" velocity="20" lower="-2.4958208303518913951" upper="0.64577182323790194296"/>
        <joint_properties friction="0.0"/>
    </joint>

    <joint name="Coxa-Femur2" type="revolute">
        <origin xyz="0.04492499999999965965 0.034150000000000325928 0.024449999999999971756" rpy="-1.5707963267948978903 -0.7853981633974617127 3.1415926535897904515" />
        <parent link="coxa_2" />
        <child link="femur_2" />
        <axis xyz="0 0 1"/>
        <limit effort="1" velocity="20" lower="-0.785398163397448279" upper="2.356194490192344837"/>
        <joint_properties friction="0.0"/>
    </joint>

    <joint name="Body-Coxa2" type="revolute">
        <origin xyz="-0.081691678706847528635 -0.12580337699943056062 0.18620000000000003215" rpy="-3.6747795376463502762e-16 7.2203401213086307816e-16 -2.1467549799530249999" />
        <parent link="body2" />
        <child link="coxa_2" />
        <axis xyz="0 0 1"/>
        <limit effort="1" velocity="20" lower="-1.0471975511965976313" upper="1.0471975511965976313"/>
        <joint_properties friction="0.0"/>
    </joint>

    <link name="coxa_3">
        <visual>
            <origin xyz="0.044924999999999742917 3.1079121142417974466e-16 0.024449999999999999512" rpy="1.570796326794896336 4.157395578127884841e-27 -2.7546667145413239648e-17" />
            <geometry>
                <mesh filename="../meshes/coxa.obj"/>
            </geometry>
            <material name="coxa_material">
                <color rgba="0.2313725490196078538 0.38039215686274507888 0.7058823529411765163 1.0"/>
            </material>
        </visual>
        <collision>
            <origin xyz="0.044924999999999742917 3.1079121142417974466e-16 0.024449999999999999512" rpy="1.570796326794896336 4.157395578127884841e-27 -2.7546667145413239648e-17" />
            <geometry>
                <mesh filename="../meshes/coxa.obj"/>
            </geometry>
        </collision>
        <inertial>
            <origin xyz="0.032100077240121822897 0.0015740371043174727645 0.033819596679097937986" rpy="0 0 0"/>
            <mass value="0.13178847096179543974" />
            <inertia ixx="0.00011206373196826075725" ixy="-2.7238887323284891978e-06" ixz="4.5419611014534278721e-06" iyy="0.00015582474539323191054" iyz="1.6739702901874809955e-06" izz="8.7721551578304402452e-05" />
        </inertial>
    </link>

    <link name="femur_3">
        <visual>
            <origin xyz="0.11831370849898506514 0 0.034149999999999944289" rpy="1.831254160643732801e-16 2.649205571285318307e-16 4.1871219668615821442e-17" />
            <geometry>
                <mesh filename="../meshes/femur.obj"/>
            </geometry>
            <material name="femur_material">
                <color rgba="0.97254901960784312376 0.52941176470588235947 0.0039215686274509803377 1.0"/>
            </material>
        </visual>
        <collision>
            <origin xyz="0.11831370849898506514 0 0.034149999999999944289" rpy="1.831254160643732801e-16 2.649205571285318307e-16 4.1871219668615821442e-17" />
            <geometry>
                <mesh filename="../meshes/femur.obj"/>
            </geometry>
        </collision>
        <inertial>
            <origin xyz="0.060855439588990208055 -1.5373120779867940733e-09 0.035514840700278313412" rpy="0 0 0"/>
            <mass value="0.12356537633038003343" />
            <inertia ixx="0.00012639156802844351245" ixy="-3.3471051787725898063e-06" ixz="4.1877477426019559444e-07" iyy="0.00033659596516426965821" iyz="-1.0699470754814436559e-13" izz="0.00024640255809226478808" />
        </inertial>
    </link>

    <link name="tibia_3">
        <visual>
            <origin xyz="0.21300366849942772851 -0.059547886795041610197 0.034350000000001171263" rpy="4.3225521203320967478e-16 2.0241611661294420628e-16 -0.27307703521910409172" />
            <geometry>
                <mesh filename="../meshes/tibia.obj"/>
            </geometry>
            <material name="tibia_material">
                <color rgba="0.49803921568627451677 0.49803921568627451677 0.49803921568627451677 1.0"/>
            </material>
        </visual>
        <collision>
            <origin xyz="0.21300366849942772851 -0.059547886795041610197 0.034350000000001171263" rpy="4.3225521203320967478e-16 2.0241611661294420628e-16 -0.27307703521910409172" />
            <geometry>
                <mesh filename="../meshes/tibia.obj"/>
            </geometry>
        </collision>
        <inertial>
            <origin xyz="0.082779557898568001395 -0.010498326624429260567 0.033115642475337062067" rpy="0 0 0"/>
            <mass value="0.17582156291145253912" />
            <inertia ixx="9.4427777285217590498e-05" ixy="0.00016508460236147433288" ixz="-1.7210628936254706146e-05" iyy="0.00087082283180923156576" iyz="2.1968964051795939281e-06" izz="0.00091072918862152333567" />
        </inertial>
    </link>

    <joint name="Femur-Tibia3" type="revolute">
        <origin xyz="0.11831370849898503739 0 0" rpy="-1.6751028778016673307e-14 1.2780556880393541527e-14 -2.4958208303519433535" />
        <parent link="femur_3" />
        <child link="tibia_3" />
        <axis xyz="0 0 1"/>
        <limit effort="1" velocity="20" lower="-2.4958208303518913951" upper="0.64577182323790194296"/>
        <joint_properties friction="0.0"/>
    </joint>

    <joint name="Coxa-Femur3" type="revolute">
        <origin xyz="0.044924999999999715161 0.034150000000000305111 0.024449999999999944" rpy="-1.570796326794896336 -0.78539816339742529738 3.1415926535897926719" />
        <parent link="coxa_3" />
        <child link="femur_3" />
        <axis xyz="0 0 1"/>
        <limit effort="1" velocity="20" lower="-0.785398163397448279" upper="2.356194490192344837"/>
        <joint_properties friction="0.0"/>
    </joint>

    <joint name="Body-Coxa3" type="revolute">
        <origin xyz="0.081700031797662345245 -0.12580337699943183738 0.1862000000000000044" rpy="3.108916988713376037e-16 -5.9055856833228724177e-16 -0.99483767363676756101" />
        <parent link="body2" />
        <child link="coxa_3" />
        <axis xyz="0 0 1"/>
        <limit effort="1" velocity="20" lower="-1.0471975511965976313" upper="1.0471975511965976313"/>
        <joint_properties friction="0.0"/>
    </joint>

    <link name="coxa_4">
        <visual>
            <origin xyz="0.044924999999999687406 3.2028136856521692566e-16 0.024449999999999999512" rpy="1.570796326794896336 4.1572969705147314971e-27 1.60894779806233028e-48" />
            <geometry>
                <mesh filename="../meshes/coxa.obj"/>
            </geometry>
            <material name="coxa_material">
                <color rgba="0.2313725490196078538 0.38039215686274507888 0.7058823529411765163 1.0"/>
            </material>
        </visual>
        <collision>
            <origin xyz="0.044924999999999687406 3.2028136856521692566e-16 0.024449999999999999512" rpy="1.570796326794896336 4.1572969705147314971e-27 1.60894779806233028e-48" />
            <geometry>
                <mesh filename="../meshes/coxa.obj"/>
            </geometry>
        </collision>
        <inertial>
            <origin xyz="0.032100077240121767386 0.0015740371043174818718 0.033819596679097937986" rpy="0 0 0"/>
            <mass value="0.13178847096179543974" />
            <inertia ixx="0.00011206373196826075725" ixy="-2.7238887323284798804e-06" ixz="4.5419611014534278721e-06" iyy="0.00015582474539323191054" iyz="1.6739702901874812073e-06" izz="8.7721551578304402452e-05" />
        </inertial>
    </link>

    <link name="femur_4">
        <visual>
            <origin xyz="0.11831370849898506514 5.5511151231257827021e-17 0.034149999999999972045" rpy="2.5412593609927095818e-16 2.872393642780046957e-16 1.0823400967471919944e-17" />
            <geometry>
                <mesh filename="../meshes/femur.obj"/>
            </geometry>
            <material name="femur_material">
                <color rgba="0.97254901960784312376 0.52941176470588235947 0.0039215686274509803377 1.0"/>
            </material>
        </visual>
        <collision>
            <origin xyz="0.11831370849898506514 5.5511151231257827021e-17 0.034149999999999972045" rpy="2.5412593609927095818e-16 2.872393642780046957e-16 1.0823400967471919944e-17" />
            <geometry>
                <mesh filename="../meshes/femur.obj"/>
            </geometry>
        </collision>
        <inertial>
            <origin xyz="0.060855439588990208055 -1.5373120205871973618e-09 0.035514840700278334229" rpy="0 0 0"/>
            <mass value="0.12356537633038003343" />
            <inertia ixx="0.00012639156802844351245" ixy="-3.347105178772594465e-06" ixz="4.1877477426023482265e-07" iyy="0.00033659596516426965821" iyz="-1.0699466472352152534e-13" izz="0.00024640255809226478808" />
        </inertial>
    </link>

    <link name="tibia_4">
        <visual>
            <origin xyz="0.21300366849942770076 -0.059547886795041582442 0.034350000000001150446" rpy="4.3217611766192796211e-16 2.3241406019702804199e-16 -0.27307703521910409172" />
            <geometry>
                <mesh filename="../meshes/tibia.obj"/>
            </geometry>
            <material name="tibia_material">
                <color rgba="0.49803921568627451677 0.49803921568627451677 0.49803921568627451677 1.0"/>
            </material>
        </visual>
        <collision>
            <origin xyz="0.21300366849942770076 -0.059547886795041582442 0.034350000000001150446" rpy="4.3217611766192796211e-16 2.3241406019702804199e-16 -0.27307703521910409172" />
            <geometry>
                <mesh filename="../meshes/tibia.obj"/>
            </geometry>
        </collision>
        <inertial>
            <origin xyz="0.082779557898567945884 -0.010498326624429232812 0.033115642475337041251" rpy="0 0 0"/>
            <mass value="0.17582156291145253912" />
            <inertia ixx="9.4427777285217617603e-05" ixy="0.00016508460236147435999" ixz="-1.7210628936254651936e-05" iyy="0.00087082283180923156576" iyz="2.1968964051795960456e-06" izz="0.00091072918862152333567" />
        </inertial>
    </link>

    <joint name="Femur-Tibia4" type="revolute">
        <origin xyz="0.11831370849898725783 1.9984014443252817728e-15 6.9388939039072283776e-18" rpy="2.0924863795462638411e-15 -1.0960168374547815724e-14 -2.4958208303518727433" />
        <parent link="femur_4" />
        <child link="tibia_4" />
        <axis xyz="0 0 1"/>
        <limit effort="1" velocity="20" lower="-2.4958208303518913951" upper="0.64577182323790194296"/>
        <joint_properties friction="0.0"/>
    </joint>

    <joint name="Coxa-Femur4" type="revolute">
        <origin xyz="0.04492499999999965965 0.034149999999999534894 0.024449999999999971756" rpy="-1.570796326794896336 -0.78539816339746482132 -3.1415926535897829019" />
        <parent link="coxa_4" />
        <child link="femur_4" />
        <axis xyz="0 0 1"/>
        <limit effort="1" velocity="20" lower="-0.785398163397448279" upper="2.356194490192344837"/>
        <joint_properties friction="0.0"/>
    </joint>

    <joint name="Body-Coxa4" type="revolute">
        <origin xyz="0.1250041765454069087 -2.7918076165541795552e-06 0.1862000000000000044" rpy="2.2204460421817382516e-16 -1.5212558864034215159e-24 -1.3596310785559686023e-32" />
        <parent link="body2" />
        <child link="coxa_4" />
        <axis xyz="0 0 1"/>
        <limit effort="1" velocity="20" lower="-1.0471975511965976313" upper="1.0471975511965976313"/>
        <joint_properties friction="0.0"/>
    </joint>

    <link name="coxa_5">
        <visual>
            <origin xyz="0.044924999999999715161 3.1874188618358223479e-16 0.024449999999999999512" rpy="1.570796326794896336 4.1572969705147401066e-27 -5.2322831974750389716e-18" />
            <geometry>
                <mesh filename="../meshes/coxa.obj"/>
            </geometry>
            <material name="coxa_material">
                <color rgba="0.2313725490196078538 0.38039215686274507888 0.7058823529411765163 1.0"/>
            </material>
        </visual>
        <collision>
            <origin xyz="0.044924999999999715161 3.1874188618358223479e-16 0.024449999999999999512" rpy="1.570796326794896336 4.1572969705147401066e-27 -5.2322831974750389716e-18" />
            <geometry>
                <mesh filename="../meshes/coxa.obj"/>
            </geometry>
        </collision>
        <inertial>
            <origin xyz="0.032100077240121795141 0.0015740371043174803539 0.033819596679097937986" rpy="0 0 0"/>
            <mass value="0.13178847096179543974" />
            <inertia ixx="0.00011206373196826075725" ixy="-2.723888732328481151e-06" ixz="4.5419611014534278721e-06" iyy="0.00015582474539323191054" iyz="1.6739702901874812073e-06" izz="8.7721551578304402452e-05" />
        </inertial>
    </link>

    <link name="femur_5">
        <visual>
            <origin xyz="0.11831370849898507902 0 0.034149999999999958167" rpy="3.2371882143153486823e-16 2.5326224038908324617e-16 5.4499384042324190178e-17" />
            <geometry>
                <mesh filename="../meshes/femur.obj"/>
            </geometry>
            <material name="femur_material">
                <color rgba="0.97254901960784312376 0.52941176470588235947 0.0039215686274509803377 1.0"/>
            </material>
        </visual>
        <collision>
            <origin xyz="0.11831370849898507902 0 0.034149999999999958167" rpy="3.2371882143153486823e-16 2.5326224038908324617e-16 5.4499384042324190178e-17" />
            <geometry>
                <mesh filename="../meshes/femur.obj"/>
            </geometry>
        </collision>
        <inertial>
            <origin xyz="0.060855439588990208055 -1.5373120786638194844e-09 0.03551484070027832729" rpy="0 0 0"/>
            <mass value="0.12356537633038003343" />
            <inertia ixx="0.00012639156802844356666" ixy="-3.3471051787725931944e-06" ixz="4.1877477426022693466e-07" iyy="0.00033659596516426965821" iyz="-1.0699465149064355961e-13" izz="0.00024640255809226478808" />
        </inertial>
    </link>

    <link name="tibia_5">
        <visual>
            <origin xyz="0.21300366849942778402 -0.059547886795041526931 0.034350000000001157385" rpy="4.5492349787498125063e-16 2.0568463924965199826e-16 -0.2730770352191039807" />
            <geometry>
                <mesh filename="../meshes/tibia.obj"/>
            </geometry>
            <material name="tibia_material">
                <color rgba="0.49803921568627451677 0.49803921568627451677 0.49803921568627451677 1.0"/>
            </material>
        </visual>
        <collision>
            <origin xyz="0.21300366849942778402 -0.059547886795041526931 0.034350000000001157385" rpy="4.5492349787498125063e-16 2.0568463924965199826e-16 -0.2730770352191039807" />
            <geometry>
                <mesh filename="../meshes/tibia.obj"/>
            </geometry>
        </collision>
        <inertial>
            <origin xyz="0.082779557898568029151 -0.010498326624429198117 0.033115642475337048189" rpy="0 0 0"/>
            <mass value="0.17582156291145253912" />
            <inertia ixx="9.4427777285217631155e-05" ixy="0.0001650846023614744142" ixz="-1.7210628936254567233e-05" iyy="0.00087082283180923134892" iyz="2.1968964051796189155e-06" izz="0.00091072918862152333567" />
        </inertial>
    </link>

    <joint name="Femur-Tibia5" type="revolute">
        <origin xyz="0.11831370849898502351 5.5511151231257827021e-17 -2.0816681711721685133e-17" rpy="7.3483943741018971237e-15 -3.1743489649724681514e-15 -2.4958208303519162641" />
        <parent link="femur_5" />
        <child link="tibia_5" />
        <axis xyz="0 0 1"/>
        <limit effort="1" velocity="20" lower="-2.4958208303518913951" upper="0.64577182323790194296"/>
        <joint_properties friction="0.0"/>
    </joint>

    <joint name="Coxa-Femur5" type="revolute">
        <origin xyz="0.044924999999999798428 0.034150000000000263478 0.024449999999999777467" rpy="-1.570796326794896336 -0.78539816339744905616 3.1415926535897908956" />
        <parent link="coxa_5" />
        <child link="femur_5" />
        <axis xyz="0 0 1"/>
        <limit effort="1" velocity="20" lower="-0.785398163397448279" upper="2.356194490192344837"/>
        <joint_properties friction="0.0"/>
    </joint>

    <joint name="Body-Coxa5" type="revolute">
        <origin xyz="0.081700031797662289734 0.12579779338419799783 0.1862000000000000044" rpy="0 -2.0497056596268378887e-58 0.9948376736367680051" />
        <parent link="body2" />
        <child link="coxa_5" />
        <axis xyz="0 0 1"/>
        <limit effort="1" velocity="20" lower="-1.0471975511965976313" upper="1.0471975511965976313"/>
        <joint_properties friction="0.0"/>
    </joint>

    <link name="coxa_6">
        <visual>
            <origin xyz="0.044924999999999715161 3.2060578218401532269e-16 0.024450000000000027267" rpy="1.570796326794896336 4.1573993778204564409e-27 7.2595459323825237006e-18" />
            <geometry>
                <mesh filename="../meshes/coxa.obj"/>
            </geometry>
            <material name="coxa_material">
                <color rgba="0.2313725490196078538 0.38039215686274507888 0.7058823529411765163 1.0"/>
            </material>
        </visual>
        <collision>
            <origin xyz="0.044924999999999715161 3.2060578218401532269e-16 0.024450000000000027267" rpy="1.570796326794896336 4.1573993778204564409e-27 7.2595459323825237006e-18" />
            <geometry>
                <mesh filename="../meshes/coxa.obj"/>
            </geometry>
        </collision>
        <inertial>
            <origin xyz="0.032100077240121795141 0.0015740371043174825223 0.033819596679097965741" rpy="0 0 0"/>
            <mass value="0.13178847096179543974" />
            <inertia ixx="0.00011206373196826075725" ixy="-2.7238887323284684455e-06" ixz="4.5419611014534278721e-06" iyy="0.00015582474539323196475" iyz="1.6739702901874816308e-06" izz="8.7721551578304402452e-05" />
        </inertial>
    </link>

    <link name="femur_6">
        <visual>
            <origin xyz="0.11831370849898502351 0 0.034149999999999951228" rpy="3.4950657378053326472e-16 2.1592120994610319396e-16 -2.2371143170756383311e-17" />
            <geometry>
                <mesh filename="../meshes/femur.obj"/>
            </geometry>
            <material name="femur_material">
                <color rgba="0.97254901960784312376 0.52941176470588235947 0.0039215686274509803377 1.0"/>
            </material>
        </visual>
        <collision>
            <origin xyz="0.11831370849898502351 0 0.034149999999999951228" rpy="3.4950657378053326472e-16 2.1592120994610319396e-16 -2.2371143170756383311e-17" />
            <geometry>
                <mesh filename="../meshes/femur.obj"/>
            </geometry>
        </collision>
        <inertial>
            <origin xyz="0.060855439588990166422 -1.5373120743693802262e-09 0.035514840700278320351" rpy="0 0 0"/>
            <mass value="0.12356537633038003343" />
            <inertia ixx="0.00012639156802844351245" ixy="-3.3471051787726058999e-06" ixz="4.1877477426020861757e-07" iyy="0.00033659596516426965821" iyz="-1.0699466506679005684e-13" izz="0.00024640255809226467966" />
        </inertial>
    </link>

    <link name="tibia_6">
        <visual>
            <origin xyz="0.21300366849942770076 -0.059547886795041554686 0.03435000000000112963" rpy="4.6257841897549165306e-16 3.0529454191982322212e-16 -0.27307703521910409172" />
            <geometry>
                <mesh filename="../meshes/tibia.obj"/>
            </geometry>
            <material name="tibia_material">
                <color rgba="0.49803921568627451677 0.49803921568627451677 0.49803921568627451677 1.0"/>
            </material>
        </visual>
        <collision>
            <origin xyz="0.21300366849942770076 -0.059547886795041554686 0.03435000000000112963" rpy="4.6257841897549165306e-16 3.0529454191982322212e-16 -0.27307703521910409172" />
            <geometry>
                <mesh filename="../meshes/tibia.obj"/>
            </geometry>
        </collision>
        <inertial>
            <origin xyz="0.082779557898567973639 -0.010498326624429205056 0.033115642475337034312" rpy="0 0 0"/>
            <mass value="0.17582156291145253912" />
            <inertia ixx="9.442777728521760405e-05" ixy="0.00016508460236147435999" ixz="-1.7210628936254685818e-05" iyy="0.00087082283180923156576" iyz="2.1968964051796163744e-06" izz="0.00091072918862152311883" />
        </inertial>
    </link>

    <joint name="Femur-Tibia6" type="revolute">
        <origin xyz="0.11831370849898502351 0 2.7755575615628913511e-17" rpy="-3.0834367248293091028e-15 1.6128782629212281045e-14 -2.4958208303518940596" />
        <parent link="femur_6" />
        <child link="tibia_6" />
        <axis xyz="0 0 1"/>
        <limit effort="1" velocity="20" lower="-2.4958208303518913951" upper="0.64577182323790194296"/>
        <joint_properties friction="0.0"/>
    </joint>

    <joint name="Coxa-Femur6" type="revolute">
        <origin xyz="0.044924999999999742917 0.034150000000000284295 0.024450000000000027267" rpy="-1.570796326794896336 -0.78539816339743806495 -3.1415926535897926719" />
        <parent link="coxa_6" />
        <child link="femur_6" />
        <axis xyz="0 0 1"/>
        <limit effort="1" velocity="20" lower="-0.785398163397448279" upper="2.356194490192344837"/>
        <joint_properties friction="0.0"/>
    </joint>

    <joint name="Body-Coxa6" type="revolute">
        <origin xyz="-0.081691678706848042113 0.1257977933841993301 0.18620000000000005991" rpy="-7.2848884411772469252e-16 1.3356900883562889889e-15 2.1467549799530236676" />
        <parent link="body2" />
        <child link="coxa_6" />
        <axis xyz="0 0 1"/>
        <limit effort="1" velocity="20" lower="-1.0471975511965976313" upper="1.0471975511965976313"/>
        <joint_properties friction="0.0"/>
    </joint>


</robot>
