<robot name="onshape">
    <link name="world"/>

    <joint name="fixed" type="fixed">
        <parent link="world"/>
        <child link="body2"/>
    </joint>
    <link name="body2">
        <visual>
            <origin xyz="-2.0251919608103787686e-07 -9.3350295535953844076e-09 0.2000000000000000111" rpy="0 -0 0" />
            <geometry>
                <mesh filename="../meshes/body2.obj"/>
            </geometry>
            <material name="body2_material">
                <color rgba="0.49803921568627451677 0.49803921568627451677 0.49803921568627451677 1.0"/>
            </material>
        </visual>
        <collision>
            <origin xyz="-2.0251919608103787686e-07 -9.3350295535953844076e-09 0.2000000000000000111" rpy="0 -0 0" />
            <geometry>
                <mesh filename="../meshes/body2.obj"/>
            </geometry>
        </collision>
        <inertial>
            <origin xyz="4.8159086971461754611e-05 -0.0014156634461524751547 0.22478087637914107022" rpy="0 0 0"/>
            <mass value="1.3612542756189531801" />
            <inertia ixx="0.0077625706777320196972" ixy="2.5091052185424148231e-06" ixz="-5.8608327827100554163e-07" iyy="0.0063611320539585245251" iyz="-1.739803642137599792e-05" izz="0.013115144217312024733" />
        </inertial>
    </link>

    <link name="coxa">
        <visual>
            <origin xyz="0.044924999999999715161 3.2028136856521692566e-16 0.024449999999999999512" rpy="1.570796326794896336 4.1572969705147322145e-27 -6.0505089188012136129e-58" />
            <geometry>
                <mesh filename="../meshes/coxa.obj"/>
            </geometry>
            <material name="coxa_material">
                <color rgba="0.2313725490196078538 0.38039215686274507888 0.7058823529411765163 1.0"/>
            </material>
        </visual>
        <collision>
            <origin xyz="0.044924999999999715161 3.2028136856521692566e-16 0.024449999999999999512" rpy="1.570796326794896336 4.1572969705147322145e-27 -6.0505089188012136129e-58" />
            <geometry>
                <mesh filename="../meshes/coxa.obj"/>
            </geometry>
        </collision>
        <inertial>
            <origin xyz="0.032100077240121795141 0.0015740371043174818718 0.033819596679097937986" rpy="0 0 0"/>
            <mass value="0.13178847096179543974" />
            <inertia ixx="0.00011206373196826075725" ixy="-2.7238887323284798804e-06" ixz="4.5419611014534278721e-06" iyy="0.00015582474539323191054" iyz="1.6739702901874812073e-06" izz="8.7721551578304402452e-05" />
        </inertial>
    </link>

    <link name="femur">
        <visual>
            <origin xyz="0.11831370849898502351 0 0.034149999999999965106" rpy="2.5412593609926780274e-16 2.8723936427800494222e-16 4.0353255554885214929e-17" />
            <geometry>
                <mesh filename="../meshes/femur.obj"/>
            </geometry>
            <material name="femur_material">
                <color rgba="0.97254901960784312376 0.52941176470588235947 0.0039215686274509803377 1.0"/>
            </material>
        </visual>
        <collision>
            <origin xyz="0.11831370849898502351 0 0.034149999999999965106" rpy="2.5412593609926780274e-16 2.8723936427800494222e-16 4.0353255554885214929e-17" />
            <geometry>
                <mesh filename="../meshes/femur.obj"/>
            </geometry>
        </collision>
        <inertial>
            <origin xyz="0.060855439588990166422 -1.5373120777950829722e-09 0.035514840700278334229" rpy="0 0 0"/>
            <mass value="0.12356537633038003343" />
            <inertia ixx="0.00012639156802844351245" ixy="-3.3471051787725817595e-06" ixz="4.1877477426023482265e-07" iyy="0.00033659596516426965821" iyz="-1.0699466471115516508e-13" izz="0.00024640255809226478808" />
        </inertial>
    </link>

    <link name="tibia">
        <visual>
            <origin xyz="0.21300366849942781178 -0.059547886795041582442 0.034350000000001150446" rpy="4.3217611766192633508e-16 2.3241406019702971832e-16 -0.2730770352191039807" />
            <geometry>
                <mesh filename="../meshes/tibia.obj"/>
            </geometry>
            <material name="tibia_material">
                <color rgba="0.49803921568627451677 0.49803921568627451677 0.49803921568627451677 1.0"/>
            </material>
        </visual>
        <collision>
            <origin xyz="0.21300366849942781178 -0.059547886795041582442 0.034350000000001150446" rpy="4.3217611766192633508e-16 2.3241406019702971832e-16 -0.2730770352191039807" />
            <geometry>
                <mesh filename="../meshes/tibia.obj"/>
            </geometry>
        </collision>
        <inertial>
            <origin xyz="0.082779557898568056906 -0.01049832662442924669 0.033115642475337041251" rpy="0 0 0"/>
            <mass value="0.17582156291145253912" />
            <inertia ixx="9.4427777285217644708e-05" ixy="0.0001650846023614744142" ixz="-1.7210628936254655325e-05" iyy="0.00087082283180923134892" iyz="2.1968964051795956221e-06" izz="0.00091072918862152333567" />
        </inertial>
    </link>

    <joint name="Femur-Tibia1" type="revolute">
        <origin xyz="0.11831370849898502351 0 -6.9388939039072283776e-18" rpy="-6.0759172493477425425e-14 3.0838881427276329573e-15 -2.4958208303518918392" />
        <parent link="femur" />
        <child link="tibia" />
        <axis xyz="0 0 1"/>
    </joint>

    <joint name="Coxa-Femur1" type="revolute">
        <origin xyz="0.044924999999999742917 0.034150000000001574929 0.024449999999999999512" rpy="-1.570796326794896336 -0.78539816339743095952 3.141592653589793116" />
        <parent link="coxa" />
        <child link="femur" />
        <axis xyz="0 0 1"/>

    </joint>

    <joint name="Body-Coxa1" type="revolute">
        <origin xyz="-0.12499582345459463173 -2.791807616543980008e-06 0.1862000000000000044" rpy="1.344277160988364166e-25 5.5511151231271693717e-17 -3.141592653589793116" />
        <parent link="body2" />
        <child link="coxa" />
        <axis xyz="0 0 1"/>

    </joint>
</robot>
