<robot name="onshape">

    <link name="world"/>

    <joint name="fixed" type="fixed">
        <parent link="world"/>
        <child link="body2"/>
      </joint>

    <link name="body2">
        <visual>
            <origin xyz="-2.0251919607972013182e-07 -9.3350295549132766837e-09 0" rpy="0 -0 0" />
            <geometry>
                <mesh filename="../meshes/body2.obj"/>
            </geometry>
            <material name="body2_material">
                <color rgba="0.49803921568627451677 0.49803921568627451677 0.49803921568627451677 1.0"/>
            </material>
        </visual>
        <collision>
            <origin xyz="-2.0251919607972013182e-07 -9.3350295549132766837e-09 0" rpy="0 -0 0" />
            <geometry>
                <mesh filename="../meshes/body2.obj"/>
            </geometry>
        </collision>
        <inertial>
            <origin xyz="4.8159086971463767161e-05 -0.0014156634461524764557 0.024780876379141083404" rpy="0 0 0"/>
            <mass value="1.3612542756189531801" />
            <inertia ixx="0.0077625706777320205645" ixy="2.5091052185424148231e-06" ixz="-5.8608327827102587042e-07" iyy="0.0063611320539585245251" iyz="-1.7398036421375984368e-05" izz="0.013115144217312024733" />
        </inertial>
    </link>

    <link name="coxa">
        <visual>
            <origin xyz="0.044924999999999687406 3.145194269415195476e-16 0.024449999999999996042" rpy="1.570796326794896336 4.1572969705147401066e-27 5.0966470094959365604e-17" />
            <geometry>
                <mesh filename="../meshes/coxa.obj"/>
            </geometry>
            <material name="coxa_material">
                <color rgba="0.2313725490196078538 0.38039215686274507888 0.7058823529411765163 1.0"/>
            </material>
        </visual>
        <collision>
            <origin xyz="0.044924999999999687406 3.145194269415195476e-16 0.024449999999999996042" rpy="1.570796326794896336 4.1572969705147401066e-27 5.0966470094959365604e-17" />
            <geometry>
                <mesh filename="../meshes/coxa.obj"/>
            </geometry>
        </collision>
        <inertial>
            <origin xyz="0.032100077240121767386 0.0015740371043174768845 0.033819596679097931047" rpy="0 0 0"/>
            <mass value="0.13178847096179543974" />
            <inertia ixx="0.0001120637319682607708" ixy="-2.7238887323284794569e-06" ixz="4.541961101453425331e-06" iyy="0.00015582474539323185633" iyz="1.6739702901874812073e-06" izz="8.7721551578304402452e-05" />
        </inertial>
    </link>

    <link name="femur">
        <visual>
            <origin xyz="0.11831370849898506514 -6.9388939039072283776e-18 0.034149999999999978983" rpy="2.5412593609926795065e-16 2.6169860213127295066e-16 -2.4651903288156618919e-32" />
            <geometry>
                <mesh filename="../meshes/femur.obj"/>
            </geometry>
            <material name="femur_material">
                <color rgba="0.97254901960784312376 0.52941176470588235947 0.0039215686274509803377 1.0"/>
            </material>
        </visual>
        <collision>
            <origin xyz="0.11831370849898506514 -6.9388939039072283776e-18 0.034149999999999978983" rpy="2.5412593609926795065e-16 2.6169860213127295066e-16 -2.4651903288156618919e-32" />
            <geometry>
                <mesh filename="../meshes/femur.obj"/>
            </geometry>
        </collision>
        <inertial>
            <origin xyz="0.060855439588990208055 -1.5373120823894589545e-09 0.035514840700278348107" rpy="0 0 0"/>
            <mass value="0.12356537633038003343" />
            <inertia ixx="0.00012639156802844351245" ixy="-3.3471051787725796419e-06" ixz="4.1877477426021486444e-07" iyy="0.00033659596516426965821" iyz="-1.0699466498548058562e-13" izz="0.0002464025580922648965" />
        </inertial>
    </link>

    <link name="tibia">
        <visual>
            <origin xyz="0.22117075446837430874 0.00010480390885179644012 0.034350000000001157385" rpy="4.3217611766192801141e-16 2.1006481850655434526e-16 -1.0400957034813095433e-32" />
            <geometry>
                <mesh filename="../meshes/tibia.obj"/>
            </geometry>
            <material name="tibia_material">
                <color rgba="0.49803921568627451677 0.49803921568627451677 0.49803921568627451677 1.0"/>
            </material>
        </visual>
        <collision>
            <origin xyz="0.22117075446837430874 0.00010480390885179644012 0.034350000000001157385" rpy="4.3217611766192801141e-16 2.1006481850655434526e-16 -1.0400957034813095433e-32" />
            <geometry>
                <mesh filename="../meshes/tibia.obj"/>
            </geometry>
        </collision>
        <inertial>
            <origin xyz="0.082543564299043192811 0.012215975630513638273 0.033115642475337048189" rpy="0 0 0"/>
            <mass value="0.17582156291145253912" />
            <inertia ixx="6.5153775351558298459e-05" ixy="-6.056210382916613126e-05" ixz="-1.7165392859817986117e-05" iyy="0.00090009683374289110175" iyz="-2.5261413588010218429e-06" izz="0.00091072918862152333567" />
        </inertial>
    </link>

    <joint name="Femur-Tibia3" type="revolute">
        <origin xyz="0.11831370849898451003 1.4398204850607498884e-16 -8.0491169285323849181e-16" rpy="-4.7097169221689461399e-16 -1.4670670663049555307e-15 -1.2663621787127591924e-16" />
        <parent link="femur" />
        <child link="tibia" />
        <axis xyz="0 0 1"/>
        <limit effort="1" velocity="20" />
        <joint_properties friction="0.0"/>
    </joint>

    <joint name="Coxa-Femur4" type="revolute">
        <origin xyz="0.044924999999999631894 0.034150000000000402256 0.024450000000000020328" rpy="1.5707963267948961139 3.330669073875466663e-16 -1.3539069738710677131e-16" />
        <parent link="coxa" />
        <child link="femur" />
        <axis xyz="0 0 1"/>
        <limit effort="1" velocity="20" />
        <joint_properties friction="0.0"/>
    </joint>

    <joint name="Body-Coxa1" type="revolute">
        <origin xyz="0.081700031797662359123 -0.12580337699943183738 -0.013800000000000003236" rpy="0 -2.0497056596268378887e-58 -0.99483767363676767204" />
        <parent link="body2" />
        <child link="coxa" />
        <axis xyz="0 0 1"/>
        <limit effort="1" velocity="20" />
        <joint_properties friction="0.0"/>
    </joint>

    <link name="coxa_2">
        <visual>
            <origin xyz="0.044924999999999715161 3.2028136856521692566e-16 0.024449999999999996042" rpy="1.570796326794896336 4.1572969705147401066e-27 0" />
            <geometry>
                <mesh filename="../meshes/coxa.obj"/>
            </geometry>
            <material name="coxa_material">
                <color rgba="0.2313725490196078538 0.38039215686274507888 0.7058823529411765163 1.0"/>
            </material>
        </visual>
        <collision>
            <origin xyz="0.044924999999999715161 3.2028136856521692566e-16 0.024449999999999996042" rpy="1.570796326794896336 4.1572969705147401066e-27 0" />
            <geometry>
                <mesh filename="../meshes/coxa.obj"/>
            </geometry>
        </collision>
        <inertial>
            <origin xyz="0.032100077240121795141 0.0015740371043174836065 0.033819596679097931047" rpy="0 0 0"/>
            <mass value="0.13178847096179543974" />
            <inertia ixx="0.0001120637319682607708" ixy="-2.7238887323284798804e-06" ixz="4.541961101453425331e-06" iyy="0.00015582474539323191054" iyz="1.6739702901874812073e-06" izz="8.7721551578304402452e-05" />
        </inertial>
    </link>

    <link name="femur_2">
        <visual>
            <origin xyz="0.11831370849898500963 -5.2041704279304212832e-18 0.034149999999999965106" rpy="2.5412593609926799995e-16 2.8723936427800499152e-16 -1.2918154649915205718e-48" />
            <geometry>
                <mesh filename="../meshes/femur.obj"/>
            </geometry>
            <material name="femur_material">
                <color rgba="0.97254901960784312376 0.52941176470588235947 0.0039215686274509803377 1.0"/>
            </material>
        </visual>
        <collision>
            <origin xyz="0.11831370849898500963 -5.2041704279304212832e-18 0.034149999999999965106" rpy="2.5412593609926799995e-16 2.8723936427800499152e-16 -1.2918154649915205718e-48" />
            <geometry>
                <mesh filename="../meshes/femur.obj"/>
            </geometry>
        </collision>
        <inertial>
            <origin xyz="0.060855439588990152544 -1.5373120806547354785e-09 0.035514840700278334229" rpy="0 0 0"/>
            <mass value="0.12356537633038003343" />
            <inertia ixx="0.00012639156802844351245" ixy="-3.3471051787725796419e-06" ixz="4.1877477426023566969e-07" iyy="0.00033659596516426965821" iyz="-1.0699466489999295363e-13" izz="0.00024640255809226478808" />
        </inertial>
    </link>

    <link name="tibia_2">
        <visual>
            <origin xyz="0.22117075446837425323 0.00010480390885179644012 0.034350000000001150446" rpy="4.3217611766192801141e-16 2.3241406019702804199e-16 -1.4619276614315914058e-47" />
            <geometry>
                <mesh filename="../meshes/tibia.obj"/>
            </geometry>
            <material name="tibia_material">
                <color rgba="0.49803921568627451677 0.49803921568627451677 0.49803921568627451677 1.0"/>
            </material>
        </visual>
        <collision>
            <origin xyz="0.22117075446837425323 0.00010480390885179644012 0.034350000000001150446" rpy="4.3217611766192801141e-16 2.3241406019702804199e-16 -1.4619276614315914058e-47" />
            <geometry>
                <mesh filename="../meshes/tibia.obj"/>
            </geometry>
        </collision>
        <inertial>
            <origin xyz="0.0825435642990431373 0.012215975630513638273 0.033115642475337041251" rpy="0 0 0"/>
            <mass value="0.17582156291145253912" />
            <inertia ixx="6.5153775351558298459e-05" ixy="-6.056210382916613126e-05" ixz="-1.7165392859818003057e-05" iyy="0.00090009683374289110175" iyz="-2.5261413588010205723e-06" izz="0.00091072918862152333567" />
        </inertial>
    </link>

    <joint name="Femur-Tibia4" type="revolute">
        <origin xyz="0.11831370849898550923 4.1633363423443370266e-17 0" rpy="-4.9303806604633689997e-31 2.4651903288156820356e-31 -1.2173662992324776569e-32" />
        <parent link="femur_2" />
        <child link="tibia_2" />
        <axis xyz="0 0 1"/>
        <limit effort="1" velocity="20" />
        <joint_properties friction="0.0"/>
    </joint>

    <joint name="Coxa-Femur3" type="revolute">
        <origin xyz="0.044924999999999770672 0.034150000000000325928 0.024449999999999964817" rpy="1.570796326794896336 -6.3779951200733000633e-32 8.3816471179732521841e-31" />
        <parent link="coxa_2" />
        <child link="femur_2" />
        <axis xyz="0 0 1"/>
        <limit effort="1" velocity="20" />
        <joint_properties friction="0.0"/>
    </joint>

    <joint name="Body-Coxa2" type="revolute">
        <origin xyz="0.1250041765454069087 -2.7918076165557054851e-06 -0.013799999999999999767" rpy="0 -2.0497056596268378887e-58 0" />
        <parent link="body2" />
        <child link="coxa_2" />
        <axis xyz="0 0 1"/>
        <limit effort="1" velocity="20" />
        <joint_properties friction="0.0"/>
    </joint>

    <link name="coxa_3">
        <visual>
            <origin xyz="0.044924999999999715161 3.1874188618358223479e-16 0.024449999999999996042" rpy="1.570796326794896336 4.1572969705147401066e-27 -5.2322831974750389716e-18" />
            <geometry>
                <mesh filename="../meshes/coxa.obj"/>
            </geometry>
            <material name="coxa_material">
                <color rgba="0.2313725490196078538 0.38039215686274507888 0.7058823529411765163 1.0"/>
            </material>
        </visual>
        <collision>
            <origin xyz="0.044924999999999715161 3.1874188618358223479e-16 0.024449999999999996042" rpy="1.570796326794896336 4.1572969705147401066e-27 -5.2322831974750389716e-18" />
            <geometry>
                <mesh filename="../meshes/coxa.obj"/>
            </geometry>
        </collision>
        <inertial>
            <origin xyz="0.032100077240121795141 0.0015740371043174820886 0.033819596679097931047" rpy="0 0 0"/>
            <mass value="0.13178847096179543974" />
            <inertia ixx="0.0001120637319682607708" ixy="-2.723888732328481151e-06" ixz="4.541961101453425331e-06" iyy="0.00015582474539323191054" iyz="1.6739702901874812073e-06" izz="8.7721551578304402452e-05" />
        </inertial>
    </link>

    <link name="femur_3">
        <visual>
            <origin xyz="0.11831370849898503739 -6.9388939039072283776e-18 0.03414999999999993735" rpy="2.5412593609926795065e-16 2.9303586994962563918e-16 -5.6320528256619424399e-32" />
            <geometry>
                <mesh filename="../meshes/femur.obj"/>
            </geometry>
            <material name="femur_material">
                <color rgba="0.97254901960784312376 0.52941176470588235947 0.0039215686274509803377 1.0"/>
            </material>
        </visual>
        <collision>
            <origin xyz="0.11831370849898503739 -6.9388939039072283776e-18 0.03414999999999993735" rpy="2.5412593609926795065e-16 2.9303586994962563918e-16 -5.6320528256619424399e-32" />
            <geometry>
                <mesh filename="../meshes/femur.obj"/>
            </geometry>
        </collision>
        <inertial>
            <origin xyz="0.0608554395889901803 -1.5373120823894589545e-09 0.035514840700278313412" rpy="0 0 0"/>
            <mass value="0.12356537633038003343" />
            <inertia ixx="0.00012639156802844351245" ixy="-3.3471051787725796419e-06" ixz="4.1877477426020152367e-07" iyy="0.00033659596516426965821" iyz="-1.0699466488059143085e-13" izz="0.00024640255809226478808" />
        </inertial>
    </link>

    <link name="tibia_3">
        <visual>
            <origin xyz="0.22117075446837425323 0.00010480390885179644012 0.034350000000001108813" rpy="4.3217611766192796211e-16 2.6548263317455461112e-16 1.0081787072942040391e-31" />
            <geometry>
                <mesh filename="../meshes/tibia.obj"/>
            </geometry>
            <material name="tibia_material">
                <color rgba="0.49803921568627451677 0.49803921568627451677 0.49803921568627451677 1.0"/>
            </material>
        </visual>
        <collision>
            <origin xyz="0.22117075446837425323 0.00010480390885179644012 0.034350000000001108813" rpy="4.3217611766192796211e-16 2.6548263317455461112e-16 1.0081787072942040391e-31" />
            <geometry>
                <mesh filename="../meshes/tibia.obj"/>
            </geometry>
        </collision>
        <inertial>
            <origin xyz="0.0825435642990431373 0.012215975630513638273 0.033115642475337006556" rpy="0 0 0"/>
            <mass value="0.17582156291145253912" />
            <inertia ixx="6.5153775351558298459e-05" ixy="-6.056210382916613126e-05" ixz="-1.716539285981801661e-05" iyy="0.00090009683374289110175" iyz="-2.5261413588010184548e-06" izz="0.00091072918862152311883" />
        </inertial>
    </link>

    <joint name="Femur-Tibia5" type="revolute">
        <origin xyz="0.11831370849898481534 3.6429192995512948983e-17 -1.249000902703301108e-16" rpy="1.3834006229995065212e-16 -7.0762546433814143664e-17 -1.4759986520692617497e-16" />
        <parent link="femur_3" />
        <child link="tibia_3" />
        <axis xyz="0 0 1"/>
        <limit effort="1" velocity="20" />
        <joint_properties friction="0.0"/>
    </joint>

    <joint name="Coxa-Femur2" type="revolute">
        <origin xyz="0.044924999999999715161 0.034150000000000388378 0.024449999999999950939" rpy="1.5707963267948961139 -2.5364511006982082905e-16 5.5234796480855927361e-17" />
        <parent link="coxa_3" />
        <child link="femur_3" />
        <axis xyz="0 0 1"/>
        <limit effort="1" velocity="20" />
        <joint_properties friction="0.0"/>
    </joint>

    <joint name="Body-Coxa3" type="revolute">
        <origin xyz="0.081700031797662289734 0.12579779338419799783 -0.013800000000000003236" rpy="0 -2.0497056596268378887e-58 0.9948376736367680051" />
        <parent link="body2" />
        <child link="coxa_3" />
        <axis xyz="0 0 1"/>
        <limit effort="1" velocity="20" />
        <joint_properties friction="0.0"/>
    </joint>

    <link name="coxa_4">
        <visual>
            <origin xyz="0.044924999999999687406 3.1806171872693703162e-16 0.024449999999999996042" rpy="1.570796326794896336 4.1572969705147401066e-27 4.1041473941498034013e-17" />
            <geometry>
                <mesh filename="../meshes/coxa.obj"/>
            </geometry>
            <material name="coxa_material">
                <color rgba="0.2313725490196078538 0.38039215686274507888 0.7058823529411765163 1.0"/>
            </material>
        </visual>
        <collision>
            <origin xyz="0.044924999999999687406 3.1806171872693703162e-16 0.024449999999999996042" rpy="1.570796326794896336 4.1572969705147401066e-27 4.1041473941498034013e-17" />
            <geometry>
                <mesh filename="../meshes/coxa.obj"/>
            </geometry>
        </collision>
        <inertial>
            <origin xyz="0.032100077240121767386 0.0015740371043174812213 0.033819596679097931047" rpy="0 0 0"/>
            <mass value="0.13178847096179543974" />
            <inertia ixx="0.0001120637319682607708" ixy="-2.7238887323285014798e-06" ixz="4.541961101453425331e-06" iyy="0.00015582474539323196475" iyz="1.6739702901874818426e-06" izz="8.7721551578304402452e-05" />
        </inertial>
    </link>

    <link name="femur_4">
        <visual>
            <origin xyz="0.11831370849898503739 -5.2041704279304212832e-18 0.034149999999999958167" rpy="2.5412593609926795065e-16 3.360544522504729367e-16 -2.4651903288156618919e-32" />
            <geometry>
                <mesh filename="../meshes/femur.obj"/>
            </geometry>
            <material name="femur_material">
                <color rgba="0.97254901960784312376 0.52941176470588235947 0.0039215686274509803377 1.0"/>
            </material>
        </visual>
        <collision>
            <origin xyz="0.11831370849898503739 -5.2041704279304212832e-18 0.034149999999999958167" rpy="2.5412593609926795065e-16 3.360544522504729367e-16 -2.4651903288156618919e-32" />
            <geometry>
                <mesh filename="../meshes/femur.obj"/>
            </geometry>
        </collision>
        <inertial>
            <origin xyz="0.0608554395889901803 -1.5373120806547354785e-09 0.035514840700278334229" rpy="0 0 0"/>
            <mass value="0.12356537633038003343" />
            <inertia ixx="0.00012639156802844351245" ixy="-3.3471051787725796419e-06" ixz="4.1877477426022555823e-07" iyy="0.00033659596516426965821" iyz="-1.0699466473660370429e-13" izz="0.00024640255809226467966" />
        </inertial>
    </link>

    <link name="tibia_4">
        <visual>
            <origin xyz="0.22117075446837430874 0.00010480390885179470539 0.034350000000001150446" rpy="4.3217611766192801141e-16 1.8315069791310153372e-16 6.0405232327088353681e-32" />
            <geometry>
                <mesh filename="../meshes/tibia.obj"/>
            </geometry>
            <material name="tibia_material">
                <color rgba="0.49803921568627451677 0.49803921568627451677 0.49803921568627451677 1.0"/>
            </material>
        </visual>
        <collision>
            <origin xyz="0.22117075446837430874 0.00010480390885179470539 0.034350000000001150446" rpy="4.3217611766192801141e-16 1.8315069791310153372e-16 6.0405232327088353681e-32" />
            <geometry>
                <mesh filename="../meshes/tibia.obj"/>
            </geometry>
        </collision>
        <inertial>
            <origin xyz="0.082543564299043192811 0.012215975630513636538 0.033115642475337034312" rpy="0 0 0"/>
            <mass value="0.17582156291145253912" />
            <inertia ixx="6.5153775351558298459e-05" ixy="-6.056210382916613126e-05" ixz="-1.7165392859818108089e-05" iyy="0.00090009683374289110175" iyz="-2.526141358801023537e-06" izz="0.00091072918862152311883" />
        </inertial>
    </link>

    <joint name="Femur-Tibia2" type="revolute">
        <origin xyz="0.11831370849898215081 -1.4918621893400541012e-16 -1.5959455978986625269e-16" rpy="3.5777035029604029855e-16 2.0321655937271765779e-16 5.9315772180439781132e-16" />
        <parent link="femur_4" />
        <child link="tibia_4" />
        <axis xyz="0 0 1"/>
        <limit effort="1" velocity="20" />
        <joint_properties friction="0.0"/>
    </joint>

    <joint name="Coxa-Femur5" type="revolute">
        <origin xyz="0.044924999999998521671 0.034150000000001623501 0.024450000000000013389" rpy="1.57079632679489678 5.5511151231257253864e-17 -6.4197576592191709227e-16" />
        <parent link="coxa_4" />
        <child link="femur_4" />
        <axis xyz="0 0 1"/>
        <limit effort="1" velocity="20" />
        <joint_properties friction="0.0"/>
    </joint>

    <joint name="Body-Coxa4" type="revolute">
        <origin xyz="-0.081691678706847792313 -0.12580337699943100471 -0.013800000000000001502" rpy="-1.9721522630525295135e-31 5.5846525289480289381e-32 -2.146754979953025444" />
        <parent link="body2" />
        <child link="coxa_4" />
        <axis xyz="0 0 1"/>
        <limit effort="1" velocity="20" />
        <joint_properties friction="0.0"/>
    </joint>

    <link name="coxa_5">
        <visual>
            <origin xyz="0.044924999999999701283 3.2028136856521692566e-16 0.024449999999999996042" rpy="1.570796326794896336 4.1572969705147401066e-27 0" />
            <geometry>
                <mesh filename="../meshes/coxa.obj"/>
            </geometry>
            <material name="coxa_material">
                <color rgba="0.2313725490196078538 0.38039215686274507888 0.7058823529411765163 1.0"/>
            </material>
        </visual>
        <collision>
            <origin xyz="0.044924999999999701283 3.2028136856521692566e-16 0.024449999999999996042" rpy="1.570796326794896336 4.1572969705147401066e-27 0" />
            <geometry>
                <mesh filename="../meshes/coxa.obj"/>
            </geometry>
        </collision>
        <inertial>
            <origin xyz="0.032100077240121781263 0.0015740371043174836065 0.033819596679097931047" rpy="0 0 0"/>
            <mass value="0.13178847096179543974" />
            <inertia ixx="0.0001120637319682607708" ixy="-2.7238887323284798804e-06" ixz="4.541961101453425331e-06" iyy="0.00015582474539323191054" iyz="1.6739702901874812073e-06" izz="8.7721551578304402452e-05" />
        </inertial>
    </link>

    <link name="femur_5">
        <visual>
            <origin xyz="0.11831370849898500963 -6.9388939039072283776e-18 0.034149999999999965106" rpy="2.5412593609926804926e-16 2.8723936427800499152e-16 0" />
            <geometry>
                <mesh filename="../meshes/femur.obj"/>
            </geometry>
            <material name="femur_material">
                <color rgba="0.97254901960784312376 0.52941176470588235947 0.0039215686274509803377 1.0"/>
            </material>
        </visual>
        <collision>
            <origin xyz="0.11831370849898500963 -6.9388939039072283776e-18 0.034149999999999965106" rpy="2.5412593609926804926e-16 2.8723936427800499152e-16 0" />
            <geometry>
                <mesh filename="../meshes/femur.obj"/>
            </geometry>
        </collision>
        <inertial>
            <origin xyz="0.060855439588990152544 -1.5373120823894589545e-09 0.035514840700278334229" rpy="0 0 0"/>
            <mass value="0.12356537633038003343" />
            <inertia ixx="0.00012639156802844351245" ixy="-3.3471051787725796419e-06" ixz="4.1877477426023566969e-07" iyy="0.00033659596516426965821" iyz="-1.0699466489999295363e-13" izz="0.00024640255809226478808" />
        </inertial>
    </link>

    <link name="tibia_5">
        <visual>
            <origin xyz="0.22117075446837425323 0.00010480390885179644012 0.034350000000001150446" rpy="4.3217611766192801141e-16 2.3241406019702804199e-16 0" />
            <geometry>
                <mesh filename="../meshes/tibia.obj"/>
            </geometry>
            <material name="tibia_material">
                <color rgba="0.49803921568627451677 0.49803921568627451677 0.49803921568627451677 1.0"/>
            </material>
        </visual>
        <collision>
            <origin xyz="0.22117075446837425323 0.00010480390885179644012 0.034350000000001150446" rpy="4.3217611766192801141e-16 2.3241406019702804199e-16 0" />
            <geometry>
                <mesh filename="../meshes/tibia.obj"/>
            </geometry>
        </collision>
        <inertial>
            <origin xyz="0.0825435642990431373 0.012215975630513638273 0.033115642475337041251" rpy="0 0 0"/>
            <mass value="0.17582156291145253912" />
            <inertia ixx="6.5153775351558298459e-05" ixy="-6.056210382916613126e-05" ixz="-1.7165392859818003057e-05" iyy="0.00090009683374289110175" iyz="-2.5261413588010205723e-06" izz="0.00091072918862152333567" />
        </inertial>
    </link>

    <joint name="Femur-Tibia1" type="revolute">
        <origin xyz="0.11831370849898500963 1.0408340855860842566e-17 0" rpy="1.9721522630525295135e-31 6.162975822918098391e-32 -5.5511151235415210273e-17" />
        <parent link="femur_5" />
        <child link="tibia_5" />
        <axis xyz="0 0 1"/>
        <limit effort="1" velocity="20" />
        <joint_properties friction="0.0"/>
    </joint>

    <joint name="Coxa-Femur6" type="revolute">
        <origin xyz="0.044924999999999729039 0.034150000000000318989 0.024449999999999985634" rpy="1.570796326794896336 -5.5511151231257913303e-17 1.1339875512552048206e-30" />
        <parent link="coxa_5" />
        <child link="femur_5" />
        <axis xyz="0 0 1"/>
        <limit effort="1" velocity="20" />
        <joint_properties friction="0.0"/>
    </joint>

    <joint name="Body-Coxa5" type="revolute">
        <origin xyz="-0.12499582345459307742 -2.7918076165578577958e-06 -0.013799999999999999767" rpy="0 -2.0497056596268378887e-58 3.141592653589793116" />
        <parent link="body2" />
        <child link="coxa_5" />
        <axis xyz="0 0 1"/>
        <limit effort="1" velocity="20" />
        <joint_properties friction="0.0"/>
    </joint>

    <link name="coxa_6">
        <visual>
            <origin xyz="0.044924999999999715161 3.286297252933553098e-16 0.024449999999999996042" rpy="1.570796326794896336 4.1572969705147401066e-27 8.3610527877475016983e-17" />
            <geometry>
                <mesh filename="../meshes/coxa.obj"/>
            </geometry>
            <material name="coxa_material">
                <color rgba="0.2313725490196078538 0.38039215686274507888 0.7058823529411765163 1.0"/>
            </material>
        </visual>
        <collision>
            <origin xyz="0.044924999999999715161 3.286297252933553098e-16 0.024449999999999996042" rpy="1.570796326794896336 4.1572969705147401066e-27 8.3610527877475016983e-17" />
            <geometry>
                <mesh filename="../meshes/coxa.obj"/>
            </geometry>
        </collision>
        <inertial>
            <origin xyz="0.032100077240121795141 0.0015740371043174907623 0.033819596679097931047" rpy="0 0 0"/>
            <mass value="0.13178847096179543974" />
            <inertia ixx="0.0001120637319682607708" ixy="-2.7238887323284476932e-06" ixz="4.541961101453425331e-06" iyy="0.00015582474539323191054" iyz="1.6739702901874816308e-06" izz="8.7721551578304402452e-05" />
        </inertial>
    </link>

    <link name="femur_6">
        <visual>
            <origin xyz="0.11831370849898503739 -6.9388939039072283776e-18 0.034149999999999985922" rpy="2.5412593609926799995e-16 2.3045516034332866973e-16 -5.5466782398352392568e-32" />
            <geometry>
                <mesh filename="../meshes/femur.obj"/>
            </geometry>
            <material name="femur_material">
                <color rgba="0.97254901960784312376 0.52941176470588235947 0.0039215686274509803377 1.0"/>
            </material>
        </visual>
        <collision>
            <origin xyz="0.11831370849898503739 -6.9388939039072283776e-18 0.034149999999999985922" rpy="2.5412593609926799995e-16 2.3045516034332866973e-16 -5.5466782398352392568e-32" />
            <geometry>
                <mesh filename="../meshes/femur.obj"/>
            </geometry>
        </collision>
        <inertial>
            <origin xyz="0.0608554395889901803 -1.5373120823894589545e-09 0.035514840700278355046" rpy="0 0 0"/>
            <mass value="0.12356537633038003343" />
            <inertia ixx="0.00012639156802844351245" ixy="-3.3471051787725796419e-06" ixz="4.187747742602459929e-07" iyy="0.00033659596516426965821" iyz="-1.0699466509005564753e-13" izz="0.00024640255809226478808" />
        </inertial>
    </link>

    <link name="tibia_6">
        <visual>
            <origin xyz="0.22117075446837441977 0.00010480390885179644012 0.034350000000001115752" rpy="4.3217611766192791281e-16 2.199241155461978547e-16 -1.4833342045849879969e-31" />
            <geometry>
                <mesh filename="../meshes/tibia.obj"/>
            </geometry>
            <material name="tibia_material">
                <color rgba="0.49803921568627451677 0.49803921568627451677 0.49803921568627451677 1.0"/>
            </material>
        </visual>
        <collision>
            <origin xyz="0.22117075446837441977 0.00010480390885179644012 0.034350000000001115752" rpy="4.3217611766192791281e-16 2.199241155461978547e-16 -1.4833342045849879969e-31" />
            <geometry>
                <mesh filename="../meshes/tibia.obj"/>
            </geometry>
        </collision>
        <inertial>
            <origin xyz="0.082543564299043276078 0.012215975630513638273 0.033115642475337006556" rpy="0 0 0"/>
            <mass value="0.17582156291145253912" />
            <inertia ixx="6.5153775351558325564e-05" ixy="-6.0562103829166144813e-05" ixz="-1.7165392859818019998e-05" iyy="0.00090009683374289110175" iyz="-2.5261413588010214194e-06" izz="0.00091072918862152333567" />
        </inertial>
    </link>

    <joint name="Femur-Tibia6" type="revolute">
        <origin xyz="0.11831370849898481534 1.561251128379126385e-16 1.8041124150158793782e-16" rpy="-1.4566306944823834331e-15 5.7838985307209528399e-16 -3.0363187458007979801e-16" />
        <parent link="femur_6" />
        <child link="tibia_6" />
        <axis xyz="0 0 1"/>
        <limit effort="1" velocity="20" />
        <joint_properties friction="0.0"/>
    </joint>

    <joint name="Coxa-Femur1" type="revolute">
        <origin xyz="0.04492499999999965965 0.034150000000000263478 0.024449999999999978695" rpy="1.570796326794896336 -1.1796119636642290707e-16 4.6723265804920645728e-16" />
        <parent link="coxa_6" />
        <child link="femur_6" />
        <axis xyz="0 0 1"/>
        <limit effort="1" velocity="20" />
        <joint_properties friction="0.0"/>
    </joint>

    <joint name="Body-Coxa6" type="revolute">
        <origin xyz="-0.081691678706847514757 0.12579779338419871948 -0.013800000000000001502" rpy="0 -2.0497056596268378887e-58 2.146754979953025444" />
        <parent link="body2" />
        <child link="coxa_6" />
        <axis xyz="0 0 1"/>
        <limit effort="1" velocity="20" />
        <joint_properties friction="0.0"/>
    </joint>


</robot>
