<robot name="onshape">

    <!-- <link name="world"/>

    <joint name="fixed" type="fixed">
        <parent link="world"/>
        <child link="body"/>
    </joint> -->

    <link name="body">
        <visual>
            <origin xyz="-0.012205647980743236647 -0.055342155193400160984 -0.11817610704853404036" rpy="0 -0 0" />
            <geometry>
                <mesh filename="meshes/body.obj"/>
            </geometry>
            <material name="body_material">
                <color rgba="0.5999999999999999778 0.5999999999999999778 0.5999999999999999778 1.0"/>
            </material>
        </visual>
        <!-- <collision>
            <origin xyz="0 0 0" rpy="0 -0 0" />  
            <geometry>
                <box size="0.1 0.1 0.1"/> 
            </geometry>
        </collision> -->
        <inertial>
            <origin xyz="0.013911591318139564233 0.14239094114380437817 -0.19577043666910912134" rpy="0 0 0"/>
            <mass value="0.93969833283231496424" />
            <inertia ixx="0.005994119293119408963" ixy="3.267775851214450012e-09" ixz="-2.7374181039632634978e-09" iyy="0.01324903424271485497" iyz="0.00032243412671214058667" izz="0.018549563223916550048" />
        </inertial>
    </link>

    <link name="suspensionleft">
        <visual>
            <origin xyz="-0.024612609458237885707 -0.0061949605951774067147 -0.18932959409960492536" rpy="-1.570796326794896558 -1.570796326794896558 0" />
            <geometry>
                <mesh filename="meshes/suspensionleft.obj"/>
            </geometry>
            <material name="suspensionleft_material">
                <color rgba="0.5999999999999999778 0.5999999999999999778 0.5999999999999999778 1.0"/>
            </material>
        </visual>
        <!-- <collision>
            <origin xyz="0 0 0" rpy="0 -0 0" />
            <geometry>
                <box size="0.1 0.1 0.1"/>
            </geometry>
        </collision> -->
        <inertial>
            <origin xyz="0.076832758681898538633 -0.096541141320755960442 0.011159030542809367237" rpy="0 0 0"/>
            <mass value="0.5006887550776022433" />
            <inertia ixx="0.0047535578781225072686" ixy="0.0039141042657135360905" ixz="-0.0003593170428973182411" iyy="0.017421602330455487201" iyz="0.00045149887395140190843" izz="0.021710763858302777052" />
        </inertial>
    </link>

    <link name="suspensionright">
        <visual>
            <origin xyz="-0.025991029583464636543 0.0033361923420151540221 -0.19281263685299121491" rpy="1.570796326794896558 1.570796326794896558 0" />
            <geometry>
                <mesh filename="meshes/suspensionright.obj"/>
            </geometry>
            <material name="suspensionright_material">
                <color rgba="0.5999999999999999778 0.5999999999999999778 0.5999999999999999778 1.0"/>
            </material>
        </visual>
        <!-- <collision>
            <origin xyz="-0.025991029583464636543 0.0033361923420151540221 -0.19281263685299121491" rpy="1.570796326794896558 1.570796326794896558 0" />
            <geometry>
                <mesh filename="meshes/suspensionright.obj"/>
            </geometry>
        <collision> -->
        <inertial>
            <origin xyz="0.076832938933751634969 0.096542274602325256483 0.011159331889716933572" rpy="0 0 0"/>
            <mass value="0.5006823809574474371" />
            <inertia ixx="0.0047535066761262472282" ixy="-0.0039140893355142300503" ixz="-0.00035933916185725185439" iyy="0.017421591836638574552" iyz="-0.00045150806146396102415" izz="0.021710693830293757017" />
        </inertial>
    </link>

    <joint name="suspension_left" type="revolute">
        <origin xyz="0.201911706720504458 0.092132180163690832742 -0.16260437190083004699" rpy="1.57079632679489678 -0 1.570796326794896558" />
        <parent link="body" />
        <child link="suspensionleft" />
        <axis xyz="0 0 1"/>
        <limit effort="100" velocity="20" lower="-0.52359877559 " upper="0.52359877559 "/>
        <joint_properties friction="0.0"/>
    </joint>

    <joint name="suspension_right" type="revolute">
        <origin xyz="-0.17408829327949054688 0.092132180163690846619 -0.16260437190083004699" rpy="-1.57079632679489678 -0 1.570796326794896558" />
        <parent link="body" />
        <child link="suspensionright" />
        <axis xyz="0 0 1"/>
        <limit effort="100" velocity="20" lower="-0.52359877559 " upper="0.52359877559 "/>
        <joint_properties friction="0.0"/>
    </joint>

    <link name="drivetrainbackrightcomposite">
        <visual>
            <origin xyz="-0.055255734160595336435 -0.052521626027595219588 -0.044870909561400051935" rpy="2.7755575615628869137e-16 -1.0471975511965976313 -4.9985380417640256227e-31" />
            <geometry>
                <mesh filename="meshes/drivetrainbackrightcomposite.obj"/>
            </geometry>
            <material name="drivetrainbackrightcomposite_material">
                <color rgba="0.5999999999999999778 0.5999999999999999778 0.5999999999999999778 1.0"/>
            </material>
        </visual>
        <!-- <collision>
            <origin xyz="-0.055255734160595336435 -0.052521626027595219588 -0.044870909561400051935" rpy="2.7755575615628869137e-16 -1.0471975511965976313 -4.9985380417640256227e-31" />
            <geometry>
                <mesh filename="meshes/drivetrainbackrightcomposite.obj"/>
            </geometry>
        <collision> -->
        <inertial>
            <origin xyz="0.015160736116931118611 -0.048352397480376667349 -0.083822623874481111406" rpy="0 0 0"/>
            <mass value="1.472999999999999865" />
            <inertia ixx="0.0056724243816014185623" ixy="-1.8135279944722993356e-05" ixz="-5.4028844232515525086e-05" iyy="0.0023840118856034565702" iyz="-8.5986783689443783648e-05" izz="0.005426627643422970125" />
        </inertial>
    </link>

    <link name="fullwheelcw">
        <contact>
            <lateral_friction value="1.0"/>
            <rolling_friction value="0.0"/>
            <stiffness value="30000"/>
            <damping value="1000"/>
        </contact>
        <visual>
            <origin xyz="0.0010673116951942507313 9.0479086787831342065e-05 0.0069517412411607137912" rpy="1.570796326794896558 1.570796326794896558 0" />
            <geometry>
                <mesh filename="meshes/fullwheelcw.obj"/>
            </geometry>
            <material name="fullwheelcw_material">
                <color rgba="0.08627450980392156743 0.31764705882352939348 0.69019607843137253944 1.0"/>
            </material>
        </visual>
        <collision>
            <geometry>
                <cylinder radius="0.125" length="0.220"/>
            </geometry>
        </collision>
        <inertial>
            <origin xyz="0.00042284219983780720574 -1.3273663729550548226e-08 -0.012448988962470271258" rpy="0 0 0"/>
            <mass value="3.5971729152518081563" />
            <inertia ixx="0.032711338109240588323" ixy="8.2687966679208047654e-08" ixz="1.6637247418929947719e-07" iyy="0.032711305020489800377" iyz="6.5481644600122309755e-08" izz="0.042781901331620936224" />
        </inertial>
    </link>

    <joint name="Fastened 1" type="fixed">
        <origin xyz="-0.22804336612550335506 0.24890712350835714206 0.023500000000000964562" rpy="1.5707963267948974462 1.1024596127327680454e-15 -2.4434609527920638783" />
        <parent link="suspensionright" />
        <child link="drivetrainfrontrightcomposite" />
        <axis xyz="0 0 1"/>
        <limit effort="100" velocity="20" />
        <joint_properties friction="0.0"/>
    </joint>

    <joint name="Fastened 2" type="fixed">
        <origin xyz="0.49492077744209195256 -0.26877206787608454164 0.023500000000003934408" rpy="1.57079632679489678 -1.423223005595372339e-16 1.0471975725922655354" />
        <parent link="suspensionleft" />
        <child link="drivetrainbackleftcomposite" />
        <axis xyz="0 0 1"/>
        <limit effort="100" velocity="20" />
        <joint_properties friction="0.0"/>
    </joint>

    <joint name="Fastened 3" type="fixed">
        <origin xyz="-0.22804336066742364464 -0.24890712891410071705 0.017500000000004012346" rpy="-1.57079632679489678 1.3230120027736914552e-16 -0.69813167940206133366" />
        <parent link="suspensionleft" />
        <child link="drivetrainfrontleftcomposite" />
        <axis xyz="0 0 1"/>
        <limit effort="100" velocity="20" />
        <joint_properties friction="0.0"/>
    </joint>

    <joint name="Fastened 4" type="fixed">
        <origin xyz="0.49492077155898839269 0.26877207793864221763 0.017500000000000986988" rpy="-1.5707963267948947816 -1.9713546364917863891e-15 2.094395102393197039" />
        <parent link="suspensionright" />
        <child link="drivetrainbackrightcomposite" />
        <axis xyz="0 0 1"/>
        <limit effort="100" velocity="20" />
        <joint_properties friction="0.0"/>
    </joint>

    <link name="drivetrainfrontrightcomposite">
        <visual>
            <origin xyz="0.036874942290070031325 0.046521626027595186503 0.022965534814974986055" rpy="3.141592653589793116 -0.69813170079773145815 2.8158177467239876177e-31" />
            <geometry>
                <mesh filename="meshes/drivetrainfrontrightcomposite.obj"/>
            </geometry>
            <material name="drivetrainfrontrightcomposite_material">
                <color rgba="0.5999999999999999778 0.5999999999999999778 0.5999999999999999778 1.0"/>
            </material>
        </visual>
        <!-- <collision>
            <origin xyz="0.036874942290070031325 0.046521626027595186503 0.022965534814974986055" rpy="3.141592653589793116 -0.69813170079773145815 2.8158177467239876177e-31" />
            <geometry>
                <mesh filename="meshes/drivetrainfrontrightcomposite.obj"/>
            </geometry>
        <collision> -->
        <inertial>
            <origin xyz="-0.015126077303788523776 0.04235239748037666202 0.083863928639558715794" rpy="0 0 0"/>
            <mass value="1.4730000000000003091" />
            <inertia ixx="0.0056290767536875327415" ixy="-1.2888099697659449418e-05" ixz="-6.1776263530126349923e-05" iyy="0.0023841865239638184576" iyz="-7.9733437779013998487e-05" izz="0.0054701499096972217365" />
        </inertial>
    </link>

    <link name="fullwheelccw">
        <contact>
            <lateral_friction value="1.0"/>
            <rolling_friction value="0.0"/>
            <stiffness value="30000"/>
            <damping value="1000"/>
        </contact>
        <visual>
            <origin xyz="0.00064188952092514295344 9.0479086786887652494e-05 0.0069517412411601031685" rpy="1.570796326794896558 1.570796326794896558 0" />
            <geometry>
                <mesh filename="meshes/fullwheelccw.obj"/>
            </geometry>
            <material name="fullwheelccw_material">
                <color rgba="0.72941176470588231506 0.25098039215686274161 0.10588235294117646912 1.0"/>
            </material>
        </visual>
        <collision>
            <geometry>
                <cylinder radius="0.125" length="0.220"/>
            </geometry>
        </collision>
        <inertial>
            <origin xyz="-2.5804613597969049216e-06 -1.249511817379481398e-08 -0.012441966173356872744" rpy="0 0 0"/>
            <mass value="3.5970896392687663479" />
            <inertia ixx="0.032710291812593488003" ixy="8.2697549461937102879e-08" ixz="1.6634211468960172099e-07" iyy="0.032710258685206605733" iyz="6.5538652170295507855e-08" izz="0.042780970522897796005" />
        </inertial>
    </link>

    <link name="drivetrainbackleftcomposite">
        <visual>
            <origin xyz="0.055017619072556811499 0.046521626027595242014 0.044458482130868337556" rpy="3.141592653589793116 -1.0471975511965980754 -2.2276305912043795656e-32" />
            <geometry>
                <mesh filename="meshes/drivetrainbackleftcomposite.obj"/>
            </geometry>
            <material name="drivetrainbackleftcomposite_material">
                <color rgba="0.5999999999999999778 0.5999999999999999778 0.5999999999999999778 1.0"/>
            </material>
        </visual>
        <!-- <collision>
            <origin xyz="0.055017619072556811499 0.046521626027595242014 0.044458482130868337556" rpy="3.141592653589793116 -1.0471975511965980754 -2.2276305912043795656e-32" />
            <geometry>
                <mesh filename="meshes/drivetrainbackleftcomposite.obj"/>
            </geometry>
        <collision> -->
        <inertial>
            <origin xyz="-0.015166693587829377377 0.042352397480376745287 0.083812305232200456917" rpy="0 0 0"/>
            <mass value="1.473000000000000087" />
            <inertia ixx="0.005671428823032622149" ixy="-1.7631921293790583032e-05" ixz="-5.4565847567393985207e-05" iyy="0.0023839682579308196959" iyz="-8.5114940931593571099e-05" izz="0.005427579574319136603" />
        </inertial>
    </link>

    <link name="fullwheelccw_2">
        <contact>
            <lateral_friction value="1.0"/>
            <rolling_friction value="0.0"/>
            <stiffness value="30000"/>
            <damping value="1000"/>
        </contact>
        <visual>
            <origin xyz="0.0010673116951952499321 9.0479086786887652494e-05 0.0069517412411599921462" rpy="1.570796326794896558 1.570796326794896558 0" />
            <geometry>
                <mesh filename="meshes/fullwheelccw.obj"/>
            </geometry>
            <material name="fullwheelccw_material">
                <color rgba="0.72941176470588231506 0.25098039215686274161 0.10588235294117646912 1.0"/>
            </material>
        </visual>
        <collision>
            <geometry>
                <cylinder radius="0.125" length="0.220"/>
            </geometry>
        </collision>
        <inertial>
            <origin xyz="0.00042284171291031013044 -1.249511817379481398e-08 -0.012441966173356983766" rpy="0 0 0"/>
            <mass value="3.5970896392687663479" />
            <inertia ixx="0.032710291812593488003" ixy="8.2697549460927121968e-08" ixz="1.6634211468960172099e-07" iyy="0.032710258685206605733" iyz="6.5538652170295507855e-08" izz="0.042780970522897796005" />
        </inertial>
    </link>

    <link name="drivetrainfrontleftcomposite">
        <visual>
            <origin xyz="-0.037239755770099761123 -0.052521626027595164077 -0.02327164967151634789" rpy="1.8116165364127612567e-16 -0.69813170079773156917 -2.0380041590265052002e-32" />
            <geometry>
                <mesh filename="meshes/drivetrainfrontleftcomposite.obj"/>
            </geometry>
            <material name="drivetrainfrontleftcomposite_material">
                <color rgba="0.5999999999999999778 0.5999999999999999778 0.5999999999999999778 1.0"/>
            </material>
        </visual>
        <!-- <collision>
            <origin xyz="-0.037239755770099761123 -0.052521626027595164077 -0.02327164967151634789" rpy="1.8116165364127612567e-16 -0.69813170079773156917 -2.0380041590265052002e-32" />
            <geometry>
                <mesh filename="meshes/drivetrainfrontleftcomposite.obj"/>
            </geometry>
        <collision> -->
        <inertial>
            <origin xyz="0.015128955598800702953 -0.048369207552535577188 -0.083889296331070617452" rpy="0 0 0"/>
            <mass value="1.4730000000000005311" />
            <inertia ixx="0.0056191590672057620953" ixy="-1.3502374493624255875e-05" ixz="-6.1654655440375859417e-05" iyy="0.0023828396945476375962" iyz="-8.0372217871712244085e-05" izz="0.0054582960890861599579" />
        </inertial>
    </link>

    <link name="fullwheelcw_2">
        <contact>
            <lateral_friction value="1.0"/>
            <rolling_friction value="0.0"/>
            <stiffness value="30000"/>
            <damping value="1000"/>
        </contact>
        <visual>
            <origin xyz="0.000641889520924060486 9.0479086787831342065e-05 0.0069517412411607137912" rpy="1.570796326794896558 1.570796326794896558 0" />
            <geometry>
                <mesh filename="meshes/fullwheelcw.obj"/>
            </geometry>
            <material name="fullwheelcw_material">
                <color rgba="0.08627450980392156743 0.31764705882352939348 0.69019607843137253944 1.0"/>
            </material>
        </visual>
        <collision>
            <geometry>
                <cylinder radius="0.125" length="0.220"/>
            </geometry>
        </collision>
        <inertial>
            <origin xyz="-2.5799744323831480183e-06 -1.3273663729550548226e-08 -0.012448988962470271258" rpy="0 0 0"/>
            <mass value="3.5971729152518081563" />
            <inertia ixx="0.032711338109240602201" ixy="8.2687966679208060889e-08" ixz="1.6637247418929950366e-07" iyy="0.032711305020489800377" iyz="6.5481644600122309755e-08" izz="0.042781901331620936224" />
        </inertial>
    </link>

    <joint name="FL_wheel" type="continuous">
        <origin xyz="0.015000000000000068834 -0.14149999999999993139 -0.085158124970780124663" rpy="1.570796326794896336 0.698131700797730681 -3.141592653589793116" />
        <parent link="drivetrainfrontleftcomposite" />
        <child link="fullwheelcw_2" />
        <axis xyz="0 0 1"/>
        <limit effort="100" velocity="20" />
        <joint_properties friction="0.0"/>
    </joint>

    <joint name="FR_wheel" type="continuous">
        <origin xyz="-0.015000000000000124345 0.13549999999999981504 0.085158124970780124663" rpy="-1.5707963267948972241 0.91539518778788819819 -3.1415926535897891192" />
        <parent link="drivetrainfrontrightcomposite" />
        <child link="fullwheelccw" />
        <axis xyz="0 0 1"/>
        <limit effort="100" velocity="20" />
        <joint_properties friction="0.0"/>
    </joint>

    <joint name="BL_wheel" type="continuous">
        <origin xyz="-0.015000000000000041078 0.13550000000000000933 0.085158124970780235685" rpy="-1.57079632679489678 1.0471975511965980754 3.141592653589793116" />
        <parent link="drivetrainbackleftcomposite" />
        <child link="fullwheelccw_2" />
        <axis xyz="0 0 1"/>
        <limit effort="100" velocity="20" />
        <joint_properties friction="0.0"/>
    </joint>

    <joint name="BR_wheel" type="continuous">
        <origin xyz="0.015000000000000263123 -0.1414999999999999869 -0.08515812497078045773" rpy="-1.5707963267948972241 -1.0471975511965978534 -9.7782227765798730881e-16" />
        <parent link="drivetrainbackrightcomposite" />
        <child link="fullwheelcw" />
        <axis xyz="0 0 1"/>
        <limit effort="100" velocity="20" />
        <joint_properties friction="0.0"/>
    </joint>

    <link name="radio">
        <visual>
            <origin xyz="0 0 0" rpy="1.570796326794896558 1.570796326794896558 0" />
            <geometry>
                <mesh filename="meshes/radio.obj"/>
            </geometry>
            <material name="radio_material">
                <color rgba="0.91764705882352937127 0.91764705882352937127 0.91764705882352937127 1.0"/>
            </material>
        </visual>
        <!-- <collision>
            <origin xyz="0 0 -0.041583953201770773589" rpy="1.570796326794896558 1.570796326794896558 0" />
            <geometry>
                <mesh filename="meshes/radio.obj"/>
            </geometry>
        </collision> -->
        <inertial>
            <origin xyz="0.00010263180776510683772 1.5858306326318977992e-19 -0.064223809060228773116" rpy="0 0 0"/>
            <mass value="0.2000000000000000111" />
            <inertia ixx="0.0003438073516519237361" ixy="6.2564772459245114566e-13" ixz="4.6188093671132065139e-07" iyy="0.00034138009881940292473" iyz="1.0028265943778459841e-29" izz="2.9206610625845624249e-05" />
        </inertial>
    </link>

    <link name="antenna">
        <visual>
            <origin xyz="0 0 0" rpy="-3.141592653589793116 2.4651903288156618919e-32 -1.0263416486754031281e-48" />
            <geometry>
                <mesh filename="meshes/antenna.obj"/>
            </geometry>
            <material name="antenna_material">
                <color rgba="0.91764705882352937127 0.91764705882352937127 0.91764705882352937127 1.0"/>
            </material>
        </visual>
        <!-- <collision>
            <origin xyz="0 0 0" rpy="-3.141592653589793116 2.4651903288156618919e-32 -1.0263416486754031281e-48" />
            <geometry>
                <mesh filename="meshes/antenna.obj"/>
            </geometry>
        </collision> -->
        <inertial>
            <origin xyz="-6.8251831286560820793e-20 -4.066818113829203339e-34 -0.45156705972675820204" rpy="0 0 0"/>
            <mass value="0.2000000000000000111" />
            <inertia ixx="0.013597825750077315379" ixy="-1.1398185877625000259e-50" ixz="-3.3427021854614069393e-34" iyy="0.013597825750077315379" iyz="1.3002083728230348252e-35" izz="1.6984341496596089196e-05" />
        </inertial>
    </link>

    <joint name="antennaMount" type="fixed">
        <origin xyz="0 0 -0.095" rpy="1.6028614105982569444e-17 -2.7755575615628923371e-16 1.570796326794896558" />
        <parent link="radio" />
        <child link="antenna" />
        <axis xyz="0 0 1"/>
        <limit effort="1" velocity="20" />
        <joint_properties friction="0.0"/>
    </joint>

    <joint name="radioMount" type="fixed">
        <origin xyz="-0.14 0.51 -0.22" rpy="3.141592653589793116 -0 1.570796326794896558" />
        <parent link="body" />
        <child link="radio" />
        <axis xyz="0 0 1"/>
        <limit effort="1" velocity="20" />
        <joint_properties friction="0.0"/>
    </joint>

    <link name="composite_part_1">
        <visual>
            <origin xyz="-0.16073232144117299836 -0.059365964434146906159 -0.15181500660255600743" rpy="-1.570796326794896558 -1.570796326794896558 0" />
            <geometry>
                <mesh filename="meshes/composite_part_1.obj"/>
            </geometry>
            <material name="composite_part_1_material">
                <color rgba="0.64705882352941179736 0.64705882352941179736 0.64705882352941179736 1.0"/>
            </material>
        </visual>
        <!-- <collision>
            <origin xyz="-0.16073232144117299836 -0.059365964434146906159 -0.15181500660255600743" rpy="-1.570796326794896558 -1.570796326794896558 0" />
            <geometry>
                <mesh filename="meshes/composite_part_1.obj"/>
            </geometry>
        </collision> -->
        <inertial>
            <origin xyz="-0.14843120397544637412 -0.03313609078625730231 -0.1327673590939615067" rpy="0 0 0"/>
            <mass value="5" />
            <inertia ixx="0.035826618092101997215" ixy="7.3930220078261677354e-05" ixz="-0.0012079392198400722494" iyy="0.047050418881050992681" iyz="0.000654396315728909936" izz="0.016056029795435775714" />
        </inertial>
    </link>

    <joint name="batteryBox" type="fixed">
        <origin xyz="-0.1426882932794905634 0.23373218016369090577 -0.14420437190083026935" rpy="1.57079632679489678 -0 -1.570796326794896558" />
        <parent link="body" />
        <child link="composite_part_1" />
        <axis xyz="0 0 1"/>
        <limit effort="1" velocity="20" />
        <joint_properties friction="0.0"/>
    </joint>

    <joint name="camera_front_camera_joint" type="fixed">
        <origin rpy="0 0.31415926535 -1.57079632679" xyz="-0.01371171  -0.06 -0.19"/>
        <parent link="body"/>
        <child link="camera_front_camera"/>
    </joint>

    <link name="camera_front_camera">
        <visual>
            <origin rpy="0 0 0" xyz="0.0 0.0 0.0"/>
            <geometry>
                <mesh filename="package://anymal_c_simple_description/meshes/depth_camera.dae" scale="1.0 1.0 1.0"/>
            </geometry>
        </visual>
        <inertial>
            <origin rpy="0 0 0" xyz="-0.021 -0.002 0.025"/>
            <mass value="0.16043"/>
            <inertia ixx="0.000637051" ixy="0.000484569" ixz="0.000424211" iyy="0.000929402" iyz="5.138e-06" izz="0.000484569"/>
        </inertial>
    </link>
    <joint name="camera_front_camera_to_camera_parent" type="fixed">
        <parent link="camera_front_camera"/>
        <child link="camera_front_camera_parent"/>
        <origin rpy="0.0 0.0 0.0" xyz="0.0255 0.0175 0.0"/>
    </joint>
    <link name="camera_front_camera_parent" model="d435i" serial_number="dummy" sensor="cameraRGB.xml"/>
    <joint name="camera_front_camera_parent_to_optical_frame" type="fixed">
        <parent link="camera_front_camera_parent"/>
        <child link="camera_front_optical_frame"/>
        <origin rpy="-1.57079632679 0.0 -1.57079632679" xyz="0.0 0.0 0.0"/>
    </joint>
    <link name="camera_front_optical_frame"/>
    <joint name="camera_front_camera_parent_to_color_frame" type="fixed">
        <parent link="camera_front_camera_parent"/>
        <child link="camera_front_color_frame"/>
        <origin rpy="0 0 0" xyz="0 0.015 0"/>
    </joint>
    <link name="camera_front_color_frame"/>
    <joint name="camera_front_color_frame_to_color_optical_frame" type="fixed">
        <parent link="camera_front_color_frame"/>
        <child link="camera_front_color_optical_frame"/>
        <origin rpy="-1.57079632679 0.0 -1.57079632679" xyz="0.0 0.0 0.0"/>
    </joint>
    <link name="camera_front_color_optical_frame"/>


    <joint name="camera_rear_camera_joint" type="fixed">
        <origin rpy="0 0.31415926535 1.57079632679" xyz="-0.01371171  0.5 -0.19"/>
        <parent link="body"/>
        <child link="camera_rear_camera"/>
    </joint>

    <link name="camera_rear_camera">
        <visual>
            <origin rpy="0 0 0" xyz="0.0 0.0 0.0"/>
            <geometry>
                <mesh filename="package://anymal_c_simple_description/meshes/depth_camera.dae" scale="1.0 1.0 1.0"/>
            </geometry>
        </visual>
        <inertial>
            <origin rpy="0 0 0" xyz="-0.021 -0.002 0.025"/>
            <mass value="0.16043"/>
            <inertia ixx="0.000637051" ixy="0.000484569" ixz="0.000424211" iyy="0.000929402" iyz="5.138e-06" izz="0.000484569"/>
        </inertial>
    </link>
    <joint name="camera_rear_camera_to_camera_parent" type="fixed">
        <parent link="camera_rear_camera"/>
        <child link="camera_rear_camera_parent"/>
        <origin rpy="0.0 0.0 0.0" xyz="0.0255 0.0175 0.0"/>
    </joint>
    <link name="camera_rear_camera_parent" model="d435i" serial_number="dummy" sensor="cameraRGB.xml"/>
    <joint name="camera_rear_camera_parent_to_optical_frame" type="fixed">
        <parent link="camera_rear_camera_parent"/>
        <child link="camera_rear_optical_frame"/>
        <origin rpy="-1.57079632679 0.0 -1.57079632679" xyz="0.0 0.0 0.0"/>
    </joint>
    <link name="camera_rear_optical_frame"/>
    <joint name="camera_rear_camera_parent_to_color_frame" type="fixed">
        <parent link="camera_rear_camera_parent"/>
        <child link="camera_rear_color_frame"/>
        <origin rpy="0 0 0" xyz="0 0.015 0"/>
    </joint>
    <link name="camera_rear_color_frame"/>
    <joint name="camera_rear_color_frame_to_color_optical_frame" type="fixed">
        <parent link="camera_rear_color_frame"/>
        <child link="camera_rear_color_optical_frame"/>
        <origin rpy="-1.57079632679 0.0 -1.57079632679" xyz="0.0 0.0 0.0"/>
    </joint>
    <link name="camera_rear_color_optical_frame"/>

    <joint name="camera_below_camera_joint" type="fixed">
        <origin rpy="1.57079632679 1.57079632679 1.57079632679" xyz="-0.01371171  0.18 -0.24"/>
        <parent link="body"/>
        <child link="camera_below_camera"/>
    </joint>

    <link name="camera_below_camera">
        <visual>
            <origin rpy="0 0 0" xyz="0.0 0.0 0.0"/>
            <geometry>
                <mesh filename="package://anymal_c_simple_description/meshes/depth_camera.dae" scale="1.0 1.0 1.0"/>
            </geometry>
        </visual>
        <inertial>
            <origin rpy="0 0 0" xyz="-0.021 -0.002 0.025"/>
            <mass value="0.16043"/>
            <inertia ixx="0.000637051" ixy="0.000484569" ixz="0.000424211" iyy="0.000929402" iyz="5.138e-06" izz="0.000484569"/>
        </inertial>
    </link>
    <joint name="camera_below_camera_to_camera_parent" type="fixed">
        <parent link="camera_below_camera"/>
        <child link="camera_below_camera_parent"/>
        <origin rpy="0.0 0.0 0.0" xyz="0.0255 0.0175 0.0"/>
    </joint>
    <link name="camera_below_camera_parent" model="d435i" serial_number="dummy" sensor="cameraRGBWide.xml"/>
    <joint name="camera_below_camera_parent_to_optical_frame" type="fixed">
        <parent link="camera_below_camera_parent"/>
        <child link="camera_below_optical_frame"/>
        <origin rpy="-1.57079632679 0.0 -1.57079632679" xyz="0.0 0.0 0.0"/>
    </joint>
    <link name="camera_below_optical_frame"/>
    <joint name="camera_below_camera_parent_to_color_frame" type="fixed">
        <parent link="camera_below_camera_parent"/>
        <child link="camera_below_color_frame"/>
        <origin rpy="0 0 0" xyz="0 0.015 0"/>
    </joint>
    <link name="camera_below_color_frame"/>
    <joint name="camera_below_color_frame_to_color_optical_frame" type="fixed">
        <parent link="camera_below_color_frame"/>
        <child link="camera_below_color_optical_frame"/>
        <origin rpy="-1.57079632679 0.0 -1.57079632679" xyz="0.0 0.0 0.0"/>
    </joint>
    <link name="camera_below_color_optical_frame"/>

    


    <joint name="camera_above_camera_joint" type="fixed">
        <origin rpy="0.0 0.75 -1.45" xyz="-0.135 0.52 0.81"/>
        <parent link="body"/>
        <child link="camera_above_camera"/>
    </joint>

    <link name="camera_above_camera">
        <visual>
            <origin rpy="0 0 0" xyz="0.0 0.0 0.0"/>
            <geometry>
                <mesh filename="package://anymal_c_simple_description/meshes/depth_camera.dae" scale="1.0 1.0 1.0"/>
            </geometry>
        </visual>
        <inertial>
            <origin rpy="0 0 0" xyz="-0.021 -0.002 0.025"/>
            <mass value="0.16043"/>
            <inertia ixx="0.000637051" ixy="0.000484569" ixz="0.000424211" iyy="0.000929402" iyz="5.138e-06" izz="0.000484569"/>
        </inertial>
    </link>
    <joint name="camera_above_camera_to_camera_parent" type="fixed">
        <parent link="camera_above_camera"/>
        <child link="camera_above_camera_parent"/>
        <origin rpy="0.0 0.0 0.0" xyz="0.0255 0.0175 0.0"/>
    </joint>
    <link name="camera_above_camera_parent" model="d435i" serial_number="dummy" sensor="cameraRGB.xml"/>
    <joint name="camera_above_camera_parent_to_optical_frame" type="fixed">
        <parent link="camera_above_camera_parent"/>
        <child link="camera_above_optical_frame"/>
        <origin rpy="-1.57079632679 0.0 -1.57079632679" xyz="0.0 0.0 0.0"/>
    </joint>
    <link name="camera_above_optical_frame"/>
    <joint name="camera_above_camera_parent_to_color_frame" type="fixed">
        <parent link="camera_above_camera_parent"/>
        <child link="camera_above_color_frame"/>
        <origin rpy="0 0 0" xyz="0 0.015 0"/>
    </joint>
    <link name="camera_above_color_frame"/>
    <joint name="camera_above_color_frame_to_color_optical_frame" type="fixed">
        <parent link="camera_above_color_frame"/>
        <child link="camera_above_color_optical_frame"/>
        <origin rpy="-1.57079632679 0.0 -1.57079632679" xyz="0.0 0.0 0.0"/>
    </joint>
    <link name="camera_above_color_optical_frame"/>

    




    <joint name="imu_camera_joint" type="fixed">
        <origin rpy="0.0 0.0 1.57079632679" xyz="-0.01371171  0.18 -0.18"/>
        <parent link="body"/>
        <child link="imu_camera"/>
    </joint>

    <link name="imu_camera">
        <visual>
            <origin rpy="0 0 0" xyz="0.0 0.0 0.0"/>
            <geometry>
                <mesh filename="package://anymal_c_simple_description/meshes/depth_camera.dae" scale="1.0 1.0 1.0"/>
            </geometry>
        </visual>
        <inertial>
            <origin rpy="0 0 0" xyz="-0.021 -0.002 0.025"/>
            <mass value="0.16043"/>
            <inertia ixx="0.000637051" ixy="0.000484569" ixz="0.000424211" iyy="0.000929402" iyz="5.138e-06" izz="0.000484569"/>
        </inertial>
    </link>
    <joint name="imu_camera_to_camera_parent" type="fixed">
        <parent link="imu_camera"/>
        <child link="imu_camera_parent"/>
        <origin rpy="0.0 0.0 0.0" xyz="0.0255 0.0175 0.0"/>
    </joint>
    <link name="imu_camera_parent" model="d435i" serial_number="dummy" sensor="imu.xml"/>
    <joint name="imu_camera_parent_to_optical_frame" type="fixed">
        <parent link="imu_camera_parent"/>
        <child link="imu_optical_frame"/>
        <origin rpy="-1.57079632679 0.0 -1.57079632679" xyz="0.0 0.0 0.0"/>
    </joint>
    <link name="imu_optical_frame"/>
    <joint name="imu_camera_parent_to_color_frame" type="fixed">
        <parent link="imu_camera_parent"/>
        <child link="imu_color_frame"/>
        <origin rpy="0 0 0" xyz="0 0.015 0"/>
    </joint>
    <link name="imu_color_frame"/>
    <joint name="imu_color_frame_to_color_optical_frame" type="fixed">
        <parent link="imu_color_frame"/>
        <child link="imu_color_optical_frame"/>
        <origin rpy="-1.57079632679 0.0 -1.57079632679" xyz="0.0 0.0 0.0"/>
    </joint>
    <link name="imu_color_optical_frame"/>


</robot>
